File: kk_manual/pandas_output.txt
temperature,time,DSC/(mW/mg),mass,Gas Flow(purge2)/(ml/min),Gas Flow(protective)/(ml/min),Sensit./(uV/mW),mass_filtered,mass_diff_unfiltered,mass_diff_filtered,mass_diff2_unfiltered,mass_diff2_filtered
303.17499999999995,4.99,0.002920088,0.9998918,50.0,20.0,5.70579,0.9998917999999999,0.00010810627594226804,0.00010810627594226803,0.002036469015660241,0.00203646901566024
303.17699999999996,5.09,0.003023458,0.9998918,50.0,20.0,5.70579,0.999886303677867,-5.541275103837506e-05,-0.00010815966054974018,0.0023520130211466027,0.002176457248470256
303.18899999999996,5.19,0.003488634,0.9998589,50.0,20.0,5.70574,0.9999102951379061,-0.00041309399522759804,-0.0003447662909188335,0.002204249012821423,0.002026278751799522
303.248,5.29,0.00457417,0.9999884,50.0,20.0,5.70551,0.9999594886540009,-0.0005355997534977064,-0.0005294062677095386,0.0015114112469016214,0.0016415423996360378
303.387,5.39,0.007404649,1.0000106,50.0,20.0,5.70497,1.00001901936512,-0.0006712168725329093,-0.0006644072311702191,0.0012755833835105881,0.0013040226336494987
303.649,5.49,0.01229157,1.000086,50.0,20.0,5.70396,1.0000918088938966,-0.0007763379278173943,-0.0007891006103086419,0.0011585016590664118,0.0009963148232963448
304.072,5.59,0.02087969,1.0002164999999998,50.0,20.0,5.70233,1.00017805452744,-0.0009578953028395176,-0.0008677045467818087,0.00022590658052627777,0.0007615316363464179
304.698,5.69,0.03256804,1.0001826,50.0,20.0,5.69991,1.000273627891817,-0.0008733037424519807,-0.0008184356561154425,0.0010932258842229828,0.0007782503575821432
305.563,5.79,0.04753486,1.0004638,50.0,20.0,5.69656,1.0003466669420311,-0.0006181661477171474,-0.0007071597368377417,0.0007750285624227998,0.0007690658158523617
306.70099999999996,5.89,0.06539327,1.0002909,50.0,20.0,5.69214,1.0004070843647224,-0.0006353663253690911,-0.0007049589073159089,0.0007269085560929964,0.0007623334007552202
308.155,5.99,0.08786097,1.0006262,50.0,20.0,5.6865,1.0004801455531762,-0.0008439010784542234,-0.0008128268120542716,0.0011027097064167518,0.0007526065995450354
309.929,6.09,0.11462,1.0005073,50.0,20.0,5.6796,1.0005734327062858,-0.0009724584840000716,-0.0008700152753901379,8.616661815250004e-05,0.0006219265982330131
312.03999999999996,6.19,0.14538,1.0007875,50.0,20.0,5.67138,1.0006626157304914,-0.0007761326498183507,-0.0008146869318342044,0.0007724703627082427,0.0006426021578922566
314.484,6.29,0.17854,1.0005721,50.0,20.0,5.66183,1.0007344554042161,-0.0007303888689094151,-0.000747719557021538,0.0006052725511765458,0.0008733065414605923
317.26,6.39,0.21389,1.0009286,50.0,20.0,5.65096,1.000812330165045,-0.0007644835625555402,-0.0006575037555476205,0.0013653569280279235,0.0013370877391677702
320.349,6.49,0.25016,1.0007663,50.0,20.0,5.63882,1.0008731229913588,-0.000436933781031712,-0.00047955959261753795,0.002013246611397443,0.0017993262241087565
323.73499999999996,6.59,0.28706,1.001004,50.0,20.0,5.62548,1.000907620463402,-0.00028900194953962455,-0.0002818849207862056,0.001941470250150663,0.0021147500866675784
327.395,6.69,0.32442,1.0008745000000001,50.0,20.0,5.61101,1.000929208257907,-0.00011334001695928464,-6.926399627163179e-05,0.0024454775845435873,0.002591607134386885
331.299,6.79,0.36097,1.0010252,50.0,20.0,5.59552,1.0009264979009491,0.00018333256721803082,0.0002198065640074161,0.0033306489909197424,0.0033630144487738984
335.42499999999995,6.89,0.39542,1.0008745000000001,50.0,20.0,5.57909,1.0008890394826544,0.000574635247851063,0.0005942592344038584,0.004191745263315481,0.0043795723178904076
339.736,6.99,0.42647,1.0007875,50.0,20.0,5.56187,1.0008119325849452,0.0009779636297793104,0.0010795577015554221,0.00565165982067109,0.0055504320468720576
344.205,7.09,0.45486,1.0007238,50.0,20.0,5.54395,1.0006835581842433,0.0016679789956626223,0.0017245225758525664,0.007009849533002155,0.00625182691010874
348.803,7.19,0.48308,1.0005294999999998,50.0,20.0,5.52544,1.0004701914371366,0.002562054919231116,0.00240022413213447,0.006099223690701108,0.005955228724716673
353.496,7.29,0.51236,1.000086,50.0,20.0,5.50649,1.0001909383981387,0.0029287513480937832,0.0029267794109353357,0.004713249545387016,0.005575024285336605
358.26099999999997,7.39,0.54309,0.9999884,50.0,20.0,5.48719,0.9998832745140522,0.00331272415250794,0.003431557217634785,0.005818494158043752,0.006508113674191405
363.07,7.49,0.57499,0.9994491999999999,50.0,20.0,5.46764,0.9995164748658205,0.00402848455426863,0.004149048821639411,0.008729889039788441,0.008670180132696997
367.89,7.59,0.60623,0.9992221000000001,50.0,20.0,5.448,0.9990711263110523,0.004994117169104584,0.005187590479579875,0.01178651880756959,0.010139432807576369
372.703,7.69,0.63412,0.9986491,50.0,20.0,5.42832,0.998492527664997,0.006614285550277543,0.006359479681535397,0.010477262124472586,0.008647730119754745
377.48299999999995,7.79,0.65535,0.997764,50.0,20.0,5.40873,0.9977730014121441,0.007530212308587636,0.0070706450500628865,0.003131755009914694,0.005453721759245051
382.20799999999997,7.89,0.66739,0.9970074,50.0,20.0,5.38932,0.9970316291098853,0.00715342533124641,0.007002112781794463,0.003906363116951195,0.00488925994259636
386.86199999999997,7.99,0.66755,0.9963057999999999,50.0,20.0,5.37015,0.9963498026066542,0.00649801690908447,0.006407996025004202,0.007598655184568037,0.007170354276267167
391.428,8.09,0.65501,0.9956787,50.0,20.0,5.35131,0.9957371256694677,0.00566294661813771,0.005515092744980335,0.010088622889033227,0.009186595157007378
395.89599999999996,8.19,0.63104,0.9950950000000001,50.0,20.0,5.33284,0.9952356292800657,0.004346178783791288,0.004466996651718207,0.010299345258008685,0.00928513810053547
400.25399999999996,8.29,0.59955,0.994868,50.0,20.0,5.31479,0.9948526621832797,0.0034228672830849405,0.003551328300755179,0.007734527618036974,0.00751606603244771
404.49800999999997,8.39,0.56438,0.9944041,50.0,20.0,5.29719,0.9945417288098712,0.002803900214665589,0.002934016202800257,0.004682293009883293,0.005171656058034216
408.62399999999997,8.49,0.52763,0.9943829,50.0,20.0,5.28005,0.9942804905977649,0.0025269825255236356,0.002573205806581913,0.0029241408854544237,0.0036631612357810833
412.62099,8.59,0.49245,0.9939712,50.0,20.0,5.26343,0.9940291637605946,0.002416335379727741,0.0022663305670747886,0.003437453719457237,0.0030637070845955516
416.491,8.69,0.46072,0.9937123,50.0,20.0,5.24733,0.9938192446668784,0.0017524132834196848,0.0019290204528208644,0.0027321632775129806,0.00230613514332379
420.24299999999994,8.79,0.43258,0.9936697,50.0,20.0,5.23169,0.9936581205733802,0.0016387460753151117,0.0018105624045663897,0.00042342980487197757,0.0015061575278641007
423.87399999999997,8.89,0.4088,0.9934639,50.0,20.0,5.21656,0.9934738075417229,0.002026982918586384,0.0019426949166009917,0.0016776497956337982,0.0012790732189456235
427.38199,8.99,0.38909,0.9933016000000001,50.0,20.0,5.20192,0.9932656080305683,0.0020915713251596912,0.0020799937087532376,0.0010159676448687621,0.001176460508140114
430.777,9.09,0.37288,0.9930861,50.0,20.0,5.18775,0.9930545203566181,0.002156656613365726,0.0021686133788334913,0.0009260732557782314,0.0013039697405201863
434.07101,9.19,0.36038,0.9926860999999999,50.0,20.0,5.17399,0.9928337299912633,0.0022430639485477855,0.0022981520468421134,0.0018475952077179753,0.002068570068406297
437.26599999999996,9.29,0.35083,0.9926107000000001,50.0,20.0,5.16064,0.9926025601879238,0.0024510709044420764,0.0025648472034491042,0.0034773978398546512,0.0030684230302577783
440.36799999999994,9.39,0.34474,0.9923623,50.0,20.0,5.14767,0.9923293729495505,0.0030284425909954393,0.002950003968802699,0.003877730771732202,0.003582046455302243
443.39199999999994,9.49,0.34164,0.9919304,50.0,20.0,5.13503,0.9920076244640266,0.0033308569632879426,0.0033023834831209897,0.0032740046625977792,0.0039057090151784664
446.342,9.59,0.34144,0.9916811,50.0,20.0,5.12269,0.9916672399580009,0.003521566337241211,0.0036752978990029516,0.004616522883500923,0.004956067858009928
449.23,9.69,0.34463,0.9912278999999999,50.0,20.0,5.11061,0.9912874848127928,0.0041650490199955925,0.004263817325253659,0.007012412185352701,0.006377563207327197
452.06399999999996,9.79,0.35052,0.9909041999999999,50.0,20.0,5.09875,0.9908236947956202,0.00509652390125126,0.005005965732108721,0.007436249266662781,0.007070616738809508
454.85398999999995,9.89,0.35935,0.9902335999999999,50.0,20.0,5.08708,0.9902809704983524,0.005702443435325222,0.005718687963117882,0.0068993122187980815,0.007057644539370162
457.60699999999997,9.99,0.37055,0.9897697,50.0,20.0,5.07556,0.9896797842143118,0.00638528486223322,0.006411994683745824,0.0070010628077380455,0.007000855546085167
460.32998999999995,10.09,0.38419,0.9890141,50.0,20.0,5.06417,0.9889994938538716,0.007176485617080175,0.007105900388717205,0.0068647575606776146,0.00730784737795125
463.03999999999996,10.19,0.3997,0.9882469,50.0,20.0,5.05284,0.9882560532193615,0.007679834088278881,0.007828616430549013,0.007989114307172696,0.008292958393678327
465.734,10.29,0.41768,0.9874361,50.0,20.0,5.04157,0.9874477407762423,0.008629431232435536,0.008747488694695708,0.010217209321769838,0.009412261191093691
468.41801,10.39,0.438,0.9866148,50.0,20.0,5.03035,0.9865147925710043,0.009973416251554568,0.009775365118384127,0.009841021757124868,0.009799293262906916
471.109,10.49,0.46093,0.9854803,50.0,20.0,5.0191,0.9854801948283713,0.010620560652107258,0.010708553668160545,0.009290513556937885,0.010217091818967584
473.80499999999995,10.59,0.48634,0.9845305000000001,50.0,20.0,5.00783,0.9843796464337538,0.011552765015551358,0.011743229129401156,0.01170243558370021,0.01155441063280918
476.505,10.69,0.51457,0.9831485999999999,50.0,20.0,4.99655,0.9831488020277598,0.013062470972805329,0.013022509728512488,0.01348663540453432,0.012979492967635998
479.22001,10.79,0.54548,0.9817543000000001,50.0,20.0,4.98521,0.9817760995632709,0.014369862080442886,0.014383520100154914,0.013675850764643727,0.01392969108230194
481.95901,10.89,0.57945,0.9802642,50.0,20.0,4.97377,0.9802720482279681,0.01572693317540086,0.015787243760326468,0.014673673349750338,0.015128261573596471
484.71299999999997,10.99,0.61587,0.9786109000000001,50.0,20.0,4.96228,0.9786280953444548,0.01720090284006659,0.01736831291852845,0.017076556372027984,0.01679060612005214
487.491,11.09,0.65447,0.9768715,50.0,20.0,4.95069,0.9768132925194096,0.01918137775821549,0.01917653614227961,0.018704261878084272,0.01791569013750119
490.288,11.19,0.69478,0.9747756,50.0,20.0,4.93903,0.9747936988993381,0.021118975436706933,0.02102911118150724,0.018083923965866333,0.017735103146504498
493.11200999999994,11.29,0.73553,0.972615,50.0,20.0,4.92726,0.9726006987815914,0.022768315074991108,0.022776390382450305,0.016802752744448757,0.016436740065968604
495.96,11.39,0.77605,0.9702813,50.0,20.0,4.9154,0.9702323844953443,0.02455850072369259,0.024352779063909973,0.014481069864561213,0.014513224951176485
498.82998999999995,11.49,0.81426,0.967711,50.0,20.0,4.90345,0.9677131178575884,0.025708712175095627,0.025668784230278765,0.01213850013645823,0.012746656921700867
501.727,11.59,0.84828,0.9651725,50.0,20.0,4.89141,0.965092788068681,0.026774871984144966,0.02685765859907777,0.01183859839602519,0.011413693918675033
504.645,11.69,0.87669,0.9624176,50.0,20.0,4.87928,0.962345223211381,0.02817630108996383,0.027990660080320254,0.010259161922844484,0.009552939467659427
507.581,11.79,0.89699,0.9594684,50.0,20.0,4.86709,0.959475865191157,0.029047403581976994,0.028823475002239,0.006363924116207009,0.007130713439811828
510.53999999999996,11.89,0.9086,0.9565627000000001,50.0,20.0,4.85481,0.956560355781855,0.02924679304997113,0.02934771112429855,0.004789711125732454,0.005734458496588354
513.518,11.99,0.91114,0.9536793,50.0,20.0,4.84247,0.953610876649753,0.02983079601649763,0.029873775223473696,0.005872582366853507,0.005879013680099197
516.51,12.09,0.90463,0.9506113,50.0,20.0,4.83008,0.950592218819734,0.030502740615553137,0.030507954588670547,0.00669619101159169,0.006501570653573862
519.52,12.19,0.89048,0.9475752,50.0,20.0,4.81763,0.9475113709388355,0.031157524878139498,0.03120044578964883,0.0070702424925592755,0.006726484339162758
522.53901,12.29,0.86998,0.9444423999999999,50.0,20.0,4.80515,0.9443534980707742,0.03198775256704778,0.03188707720977614,0.006451734378853713,0.0064656685181985
525.573,12.39,0.84514,0.9411261000000001,50.0,20.0,4.79263,0.9411261858701068,0.03248766655526936,0.03248410746175372,0.005717840829593257,0.006511264903676124
528.615,12.49,0.8177,0.9378967,50.0,20.0,4.78008,0.9378568698512079,0.032966836589828574,0.033109189178897,0.007215036217371518,0.007899789538605933
531.66401,12.59,0.78903,0.9345262,50.0,20.0,4.76753,0.9345183623849082,0.0338456065592041,0.033987687256306395,0.010530738059283618,0.01057900303725222
534.72101,12.69,0.75987,0.931177,50.0,20.0,4.75495,0.9310785653910343,0.03504671895892386,0.035220491754005295,0.013965353377877854,0.013466449162574159
537.779,12.79,0.73098,0.9275582,50.0,20.0,4.74239,0.9274888335137298,0.03677714131562482,0.03672072715469225,0.015756321353242342,0.016045982433691305
540.8399999999999,12.89,0.70272,0.9237452,50.0,20.0,4.72984,0.9237361105825493,0.03820850875821691,0.038389539873205175,0.01817654105499278,0.0193934173657905
543.9,12.99,0.67533,0.9199969,50.0,20.0,4.7173,0.9198324709454019,0.04008394641302715,0.040493044647319315,0.024351316016712587,0.024182913126408113
546.96201,13.09,0.64875,0.9158263,50.0,20.0,4.70478,0.9156768057306333,0.043149383490039384,0.043235917014256345,0.029915406097690944,0.02892738166867707
550.02,13.19,0.62271,0.9113001,50.0,20.0,4.69229,0.9112008620085754,0.04632765463480837,0.04636600996685831,0.032442766741361595,0.032494889137647615
553.0709899999999,13.29,0.59727,0.906515,50.0,20.0,4.67984,0.906411901451666,0.049521795778495914,0.04974797501353325,0.035462214079282184,0.03557976961481031
556.1189899999999,13.39,0.57161,0.9015241,50.0,20.0,4.66743,0.9012720130449995,0.053391066597853865,0.053473555031721354,0.038892918176769875,0.038661944215682205
559.1619900000001,13.49,0.54518,0.89582,50.0,20.0,4.65506,0.89572986439193,0.05740681561993455,0.05749316431293311,0.04148636116166893,0.0416218844241966
562.1959899999999,13.59,0.51688,0.8900627,50.0,20.0,4.64275,0.8897861190626994,0.06159227895108188,0.06179667174177721,0.044687512699127296,0.04442370037584306
565.219,13.69,0.48587,0.8835276000000001,50.0,20.0,4.6305,0.8833887643755617,0.06638778610334128,0.06640780608781495,0.04722617505126969,0.04660065113534472
568.236,13.79,0.45192,0.8767326,50.0,20.0,4.61829,0.8765116046491382,0.07115802435987462,0.07118025862527322,0.04799355533347116,0.04775541594732231
571.24799,13.89,0.41456,0.869408,50.0,20.0,4.60613,0.8691527042720322,0.07601488720587213,0.07598675398809812,0.04816498516634127,0.04835108223173165
574.24799,13.99,0.37394,0.8615219999999999,50.0,20.0,4.59404,0.8613153490976247,0.08072919670878065,0.08083915079144333,0.04903257098594782,0.04886533871161177
577.2439899999999,14.09,0.3313,0.8533557999999999,50.0,20.0,4.58198,0.8529929011124632,0.08580767936918932,0.0857857441890579,0.04959680933860877,0.048783974851003595
580.23099,14.19,0.2893,0.8442919000000001,50.0,20.0,4.56999,0.8441558063726248,0.09082975075794764,0.09067447753387431,0.04780325647006389,0.047481911948876826
583.21201,14.29,0.24664,0.8350994,50.0,20.0,4.55803,0.834843092613084,0.09540503181821691,0.09531705511061245,0.04511861716654231,0.04568190350110299
586.184,14.39,0.20559,0.8252151000000001,50.0,20.0,4.54614,0.8250797737768851,0.09978603851114798,0.09974856333894534,0.043956229074733066,0.04481465606853115
589.155,14.49,0.16846,0.8151259000000001,50.0,20.0,4.53428,0.8148946841708884,0.10398446216326107,0.10420462577638794,0.045462674593526486,0.04485343334337367
592.1189899999999,14.59,0.13633,0.8044744,50.0,20.0,4.52247,0.804253936055274,0.10893677520724765,0.10878799357946142,0.04534986356616866,0.04382084325014183
595.07599,14.69,0.11022,0.7933261,50.0,20.0,4.5107,0.7931211007915018,0.1134878650591915,0.1130987663675373,0.04044129944476893,0.0411279677037382
598.03501,14.79,0.0904874,0.7816484,50.0,20.0,4.49896,0.7816008221183665,0.11682605447675343,0.11695702530378352,0.03773199959113693,0.039062835427286016
600.98701,14.89,0.07703751,0.7700575999999999,50.0,20.0,4.48726,0.7697361985995613,0.1206635945453911,0.12079912807451011,0.03922435313536887,0.03837556004412783
603.94199,14.99,0.06944718,0.7576125,50.0,20.0,4.47558,0.757450627717529,0.12496996732632226,0.12469179292289805,0.03780923094298938,0.03722302603952344
606.88901,15.09,0.06685348,0.7449308000000001,50.0,20.0,4.46396,0.7447745857254057,0.12839546331812812,0.1282887976097393,0.03442649803606823,0.035787210346151746
609.83701,15.19,0.06876633,0.7318809000000001,50.0,20.0,4.45235,0.7317814358253799,0.13152702149087503,0.13172286123887078,0.03510644634460647,0.0362148414063076
612.7869900000001,15.29,0.07492226,0.7186802,50.0,20.0,4.44077,0.7184479320417518,0.13524695107403772,0.1354139304566782,0.03883591320487767,0.038515584215342465
615.72999,15.39,0.08417205,0.7049287,50.0,20.0,4.42923,0.7047185885023506,0.1393887535199667,0.13945035622436736,0.04148992056096201,0.04063941838127444
618.67899,15.49,0.09602335,0.6907878,50.0,20.0,4.4177,0.6905642662013796,0.1436914173401007,0.14362920942451848,0.041742161890090834,0.041484258904154254
621.63099,15.59,0.11041,0.6761725,50.0,20.0,4.40619,0.6759881213755903,0.14778900638487613,0.14777207007136914,0.041233887143828696,0.04201437341230162
624.57999,15.69,0.12743,0.6612644,50.0,20.0,4.39471,0.6610085388752951,0.1518209469949241,0.15194689366399536,0.04281459843805813,0.044010544311102545
627.5369900000001,15.79,0.1465,0.6458383000000001,50.0,20.0,4.38323,0.6456149472643856,0.15614396226026628,0.15644842302949,0.047688894398186576,0.04811881158340022
630.49299,15.89,0.16845,0.6300992,50.0,20.0,4.37178,0.6297510010322022,0.16129851904947756,0.16151985182524206,0.05361196291215897,0.053304046137705036
633.452,15.99,0.19302,0.6135503,50.0,20.0,4.36034,0.6133366932223719,0.16700273948731237,0.16712566173710597,0.0583797029908979,0.05852846707312787
636.421,16.09,0.2199,0.5966119,50.0,20.0,4.3489,0.5963463957785119,0.17290187806711188,0.1732171922205259,0.06368213333596096,0.06387977965576296
639.39301,16.19,0.2498,0.5791016,50.0,20.0,4.33747,0.5787241517442532,0.17969371849380877,0.17988051478649084,0.0694964036473813,0.06975766498432442
642.36301,16.29,0.2828,0.5607157,50.0,20.0,4.32608,0.5603956219266424,0.18689004213933558,0.18711284350388405,0.07547331008344216,0.07699723762178107
645.3389999999999,16.39,0.31721,0.5417346,50.0,20.0,4.31469,0.5413327676309249,0.19451953034215919,0.19513465150690593,0.0860428801252695,0.08564020986867969
648.31501,16.49,0.35373,0.5219013,50.0,20.0,4.30333,0.5214421455722338,0.20369740185374496,0.20438884114424705,0.09769792311891301,0.08910491213456694
651.2919999999999,16.59,0.38979,0.5011828,50.0,20.0,4.292,0.5005037688599792,0.21526545686643317,0.2139178008076706,0.08684632012702309,0.07555806650602337
654.275,16.69,0.42339,0.4781625,50.0,20.0,4.28068,0.478505122151716,0.22334114160167573,0.22061614883774988,0.043297512619348666,0.04776703899714934
657.25699,16.79,0.4515,0.45596359999999997,50.0,20.0,4.26939,0.4561044410330666,0.22380124169490756,0.2224283092063156,0.00588467500527301,0.03645550431369334
660.241,16.89,0.46847,0.4336884,50.0,20.0,4.25812,0.43381584659614314,0.22165438433031426,0.2194799467917464,0.05522417469058993,0.06736147922566967
663.223,16.99,0.46839,0.4113601,50.0,20.0,4.24689,0.4119375147459459,0.21445469893519586,0.21059613284221487,0.12678643856103733,0.1315781640267943
666.21,17.09,0.44577,0.39028399999999996,50.0,20.0,4.23567,0.391271159530899,0.1970928074205851,0.19367264529747566,0.21138953606307886,0.20667023593402659
669.198,17.19,0.39527,0.3719523,50.0,20.0,4.22448,0.3727979751279347,0.17126393560018016,0.16876219304303247,0.28328183740286406,0.2720594738710564
672.1869899999999,17.29,0.31811,0.3554459,50.0,20.0,4.21332,0.3572176887948956,0.13931881255527045,0.13789370716181776,0.32813494482378935,0.30968753554549766
675.17899,17.39,0.22223,0.3435951,50.0,20.0,4.20218,0.3450783541045357,0.10331019310142864,0.10467700649901113,0.32658352541024005,0.30561695396074273
678.172,17.49,0.12414,0.33515839999999997,50.0,20.0,4.19106,0.33643602703070696,0.07082150674026266,0.0744431024785284,0.2699879278879287,0.25859852102385494
681.16599,17.59,0.03933097,0.32996250000000005,50.0,20.0,4.17998,0.33059430219548863,0.04780929862652883,0.051649440221491684,0.18434821075025853,0.1865788754174174
684.1650099999999,17.69,-0.02527051,0.3262355,50.0,20.0,4.1689,0.32654699489107936,0.034579912662120904,0.03730193243375542,0.10613119602221555,0.1156144555264335
687.1619900000001,17.79,-0.07248424,0.323297,50.0,20.0,4.15787,0.3234597813762102,0.028006472224831214,0.029568167140106547,0.05314437415019291,0.06280175822734256
690.159,17.89,-0.10601,0.3207807,50.0,20.0,4.14687,0.3208222561322837,0.025189788251008594,0.02585770377129734,0.024658251238574902,0.03120381274284867
693.16001,17.99,-0.13059,0.3183495,50.0,20.0,4.13589,0.3183726688809306,0.02389820286250277,0.024096568925859773,0.012435651875879028,0.015109206395918735
696.154,18.09,-0.14911,0.31607,50.0,20.0,4.12496,0.31603364988836674,0.022939878685114934,0.02317890525232009,0.0062115491130643186,0.007038162451066688
699.1479899999999,18.19,-0.16248,0.31372669999999997,50.0,20.0,4.11407,0.31376486410439564,0.02257805436177307,0.022841447367399556,0.0007022366640336841,0.002903718432289759
702.141,18.29,-0.1736,0.3114897,50.0,20.0,4.10322,0.3114914604220222,0.02296634599031222,0.02293806121610296,0.0017960391550295718,0.0016860199515036961
705.13401,18.39,-0.18188,0.3091996,50.0,20.0,4.09239,0.30917628211848697,0.023246047446995988,0.023022415090791705,0.000916323476169989,0.002831180000189173
708.124,18.49,-0.18788,0.3068341,50.0,20.0,4.08162,0.30686087053298416,0.02295378939259507,0.022660301997492718,0.006379218649805063,0.005523780195961155
711.1139900000001,18.59,-0.19225,0.30446860000000003,50.0,20.0,4.07087,0.304614804051746,0.02182292952275766,0.021841552122647444,0.009016415976638381,0.006958301938543673
714.102,18.69,-0.19485,0.3026326,50.0,20.0,4.06017,0.30249593338193026,0.020726449733976082,0.021065727856388872,0.005726092677810879,0.0053778793883691185
717.0889999999999,18.79,-0.19591,0.30033180000000004,50.0,20.0,4.0495,0.30043151524652867,0.020664727556260587,0.02071998790270737,0.0016526629658342173,0.0028953208072528213
720.07401,18.89,-0.19533,0.2983867,50.0,20.0,4.03887,0.2983632958174502,0.020662139667269486,0.020607345742066605,0.0012015805829117543,0.0021931190510481907
723.05601,18.99,-0.19313,0.29635649999999997,50.0,20.0,4.02829,0.2963031055355552,0.020520538422003298,0.020397879221881736,0.0032589328193721734,0.0035653244319517738
726.038,19.09,-0.18973,0.2942605,50.0,20.0,4.01774,0.2942695614176838,0.020067964995625687,0.01992915130782874,0.0060826098748383295,0.005682147424839217
729.017,19.19,-0.18501,0.292327,50.0,20.0,4.00723,0.2923035932295067,0.019220099472303076,0.019221409140525832,0.007766156807828772,0.007172833750072744
731.999,19.29,-0.17951,0.2905229,50.0,20.0,3.99675,0.2904224269202872,0.018431442931539976,0.01842754340837602,0.007917028712423946,0.0074233696106622655
734.9759899999999,19.39,-0.1734,0.2885671,50.0,20.0,3.98632,0.2886192958344273,0.017599702744133694,0.017676151508218888,0.006866545517858036,0.006544482670907598
737.95399,19.49,-0.16757,0.2869253,50.0,20.0,3.97592,0.2868968030437844,0.016955460503805142,0.017092465714399104,0.004796817174326007,0.00529969930264089
740.9379899999999,19.59,-0.16109,0.2852073,50.0,20.0,3.96553,0.28521168401865854,0.016743276860815115,0.016666900541277976,0.004143866735975998,0.00487259135334989
743.9169999999999,19.69,-0.15409,0.28356549999999997,50.0,20.0,3.9552,0.28355939921102036,0.016261294163005147,0.01619101909054738,0.005584789833527504,0.005505398907495583
746.8970099999999,19.79,-0.14747,0.2819566,50.0,20.0,3.94489,0.28196262726216287,0.015631041982459237,0.015553579154643853,0.006883790826706204,0.005885664350085892
749.88001,19.89,-0.14118,0.280368,50.0,20.0,3.93461,0.2804457214585068,0.014700288038120846,0.014915670215729317,0.005265127179286844,0.004944399222367281
752.8639900000001,19.99,-0.13586,0.2790393,50.0,20.0,3.92435,0.278999443172032,0.014413451024234192,0.014550284899909208,0.0024054268341956453,0.00403832540325003
755.8490099999999,20.09,-0.1304,0.2774942,50.0,20.0,3.91413,0.2775449112842575,0.014602221657961323,0.014259058229212277,0.004452334717065298,0.0051941122875898745
758.83399,20.19,-0.12569,0.2759936,50.0,20.0,3.90394,0.27611775038369424,0.013727569517403282,0.013573323353228545,0.008865532392393183,0.00703081647539812
761.8209899999999,20.29,-0.1217,0.2747828,50.0,20.0,3.89378,0.2748149591609011,0.012404366644400255,0.012681185827930146,0.007813760018834714,0.006414807743670364
764.81,20.39,-0.11766,0.2735082,50.0,20.0,3.88365,0.273607102079197,0.01191247946991858,0.012148207780713629,0.0027852652067428263,0.003676892533662695
767.8030200000001,20.49,-0.11425,0.2723844,50.0,20.0,3.87353,0.27241096128097453,0.012058020669503122,0.012028004880633209,0.0004453156424785165,0.0020576793546595177
770.79499,20.59,-0.11064,0.2712075,50.0,20.0,3.86346,0.27119944099788995,0.012097906685202275,0.011903691118337247,0.0026188422833300917,0.0030210876194116994
773.7900099999999,20.69,-0.10748,0.2699542,50.0,20.0,3.85341,0.2700098084514579,0.011597339415356345,0.011468710925899626,0.005842596545405532,0.004796110317690508
776.78501,20.79,-0.10452,0.2688738,50.0,20.0,3.84339,0.2688933892433518,0.010722365524125976,0.010840315258596538,0.006059058015031038,0.00501184229584411
779.78199,20.89,-0.10201,0.2678911,50.0,20.0,3.8334,0.26785208500280716,0.010211014617228287,0.01035477986580584,0.003423166653510168,0.0033880972147050594
782.78,20.99,-0.09935957,0.26687550000000004,50.0,20.0,3.82344,0.2668383414666774,0.010076720172618181,0.010153882010208082,0.0007416843612003676,0.0015132948154922413
785.78,21.09,-0.09735649,0.2658599,50.0,20.0,3.81351,0.2658325114109659,0.010104556436349554,0.010161696886128318,0.0005370132064048683,0.0007864808193431284
788.78,21.19,-0.09493506,0.2648009,50.0,20.0,3.80361,0.2648073891772737,0.010365455808310386,0.010166049217989,0.000922304436008381,0.0013371421557610674
791.7790299999999,21.29,-0.09323854,0.2637331,50.0,20.0,3.79375,0.26378277790911614,0.009999055096191256,0.00995204019391096,0.003035409764654051,0.0021541462108846097
794.78,21.39,-0.09133768,0.2627494,50.0,20.0,3.78391,0.26281230073270845,0.009495046761854198,0.009666455595458702,0.0022224507042033492,0.0022169650911080807
797.78202,21.49,-0.0900122,0.2618749,50.0,20.0,3.77411,0.26186267886178693,0.009559054668267564,0.009507664076374165,0.0013961373945576838,0.0022966804810711384
800.7850099999999,21.59,-0.0890512,0.2609453,50.0,20.0,3.76434,0.26090650865193515,0.009461685545494092,0.009282876229103084,0.0034292331768120965,0.0032327879529702426
803.78599,21.69,-0.08749519,0.25997319999999996,50.0,20.0,3.75461,0.2599896999672511,0.008823218229871088,0.008842195644170896,0.004899624601886865,0.003821538395135806
806.7889799999999,21.79,-0.08608796,0.2591412,50.0,20.0,3.7449,0.2591391829394912,0.008251275256281332,0.008415328743983999,0.0031906097938497746,0.0029439509885742527
809.79099,21.89,-0.08431732,0.2583846,50.0,20.0,3.73524,0.2583229611552866,0.008153756370772314,0.00822595507481088,0.000827186667064439,0.0016223709398582502
812.79801,21.99,-0.08259646,0.2575207,50.0,20.0,3.72559,0.25750162984616404,0.008251177873903615,0.008168260437294786,0.0007793142996314062,0.0014391028481312807
815.80503,22.09,-0.08066753,0.2566356,50.0,20.0,3.71597,0.25668210132947916,0.008094445579672538,0.008009929176987951,0.0025116393821009164,0.002423981879070553
818.8080199999999,22.19,-0.07876739,0.2558684,50.0,20.0,3.7064,0.2558892322218044,0.007728978616405868,0.007675080789130965,0.0039864277586434405,0.0032841553357726484
821.8119899999999,22.29,-0.07755477,0.2550576,50.0,20.0,3.69686,0.2551424801074303,0.007197139913987627,0.007276123659467639,0.0035780543184055214,0.00291478604700185
824.81602,22.39,-0.0765951,0.254388,50.0,20.0,3.68735,0.2544426712310908,0.00687439287350422,0.007031607336849488,0.0010995047862811247,0.0016955241528605809
827.82102,22.49,-0.07621116,0.253784,50.0,20.0,3.67788,0.25375236641311855,0.006991279827348151,0.007043071437514874,0.0009619367566141568,0.0010470574454109044
830.822,22.59,-0.07582429,0.2530709,50.0,20.0,3.66845,0.25303903068255884,0.007264642076705741,0.007110276655233952,0.000295705363197174,0.0017780707060511386
833.82603,22.69,-0.07565657,0.2522602,50.0,20.0,3.65904,0.2523127240225214,0.007133239197642638,0.006888084769163477,0.0042500989342968976,0.003460748552354213
836.82999,22.79,-0.07560852,0.2515799,50.0,20.0,3.64966,0.2516387126374707,0.0062680605881269,0.006347394734336597,0.005645371912177399,0.004026556985027222
839.83402,22.89,-0.07537727,0.2511257,50.0,20.0,3.64032,0.25105161045261015,0.005619133673095078,0.005950717918172439,0.0015804504349573034,0.0031064224216624356
842.83298,22.99,-0.07536718,0.2505527,50.0,20.0,3.63102,0.2504811530849964,0.0059290149854618335,0.006053368659201645,0.003172785652176102,0.002856926092391649
845.83402,23.09,-0.07496975,0.2498937,50.0,20.0,3.62176,0.24985613444819368,0.006538311695411636,0.006442862914402661,0.003860401451404538,0.0028662710513964675
848.83402,23.19,-0.07467158,0.2492241,50.0,20.0,3.61252,0.24918425980449435,0.006856585947909721,0.006712075299179476,0.0011193944321341576,0.002375788117116821
851.83799,23.29,-0.07473975,0.2484897,50.0,20.0,3.60331,0.248494337773691,0.00684931438199321,0.006622847156927571,0.002877506520727602,0.0027442654488795794
854.83298,23.39,-0.07486858,0.2478529,50.0,20.0,3.59416,0.24783869874619446,0.006167919612892092,0.006217142843888596,0.00446510983296905,0.0031536897360018063
857.83201,23.49,-0.07483315,0.24722570000000002,50.0,20.0,3.58502,0.24725655793359694,0.0056196139938844425,0.005876434859853394,0.0019724446613069713,0.0022389973318974257
860.82603,23.59,-0.07467286,0.2467078,50.0,20.0,3.57593,0.24668328713004217,0.005909268251741651,0.005778891185420052,0.0005858338622654613,0.001176974830945208
863.822,23.69,-0.07498661,0.2460159,50.0,20.0,3.56687,0.24609427804568576,0.00570071997555921,0.0056888145868763335,0.001050882600401759,0.0008168944969299026
866.814,23.79,-0.07633711,0.24559460000000002,50.0,20.0,3.55785,0.24554733432810055,0.005409107091358223,0.005657309608855449,0.0006982989350741708,0.0008141172091914516
869.80698,23.89,-0.07669673,0.24506509999999998,50.0,20.0,3.54886,0.24497828191768692,0.005987076713289241,0.005767740896041098,0.0007738867967976848,0.0010525856766944335
872.7959999999999,23.99,-0.07747377,0.244266,50.0,20.0,3.53991,0.2443795017034279,0.005815058320779443,0.005709555661545484,0.0019375130194118073,0.001523789814535049
875.78202,24.09,-0.07854619,0.24383400000000002,50.0,20.0,3.531,0.24382320771212615,0.005372137533591115,0.005469902573995919,0.0022161996400096307,0.0016280564994694334
878.7669999999999,24.19,-0.07918372,0.2432397,50.0,20.0,3.52212,0.24329503307458844,0.005220254954153347,0.005359249310061686,0.00022732915258444342,0.0013911309767756445
881.75199,24.29,-0.08055823,0.24286100000000002,50.0,20.0,3.51327,0.2427673390568013,0.005430222718944222,0.005498129523924601,0.002117475558661208,0.0014638628346452186
884.7319699999999,24.39,-0.08238042,0.24217,50.0,20.0,3.50447,0.24219871390402842,0.005896992141597224,0.00564849566914578,0.00015312013387364098,0.0019715348075348485
887.71097,24.49,-0.08433754,0.2415439,50.0,20.0,3.4957,0.24161441458523308,0.005623876423404894,0.005456556143591427,0.0038283778158184067,0.00312493403195045
890.6880199999999,24.59,-0.08634593,0.241025,50.0,20.0,3.48696,0.24109062824727115,0.004877744919367544,0.004995216422161025,0.004676475850547618,0.0036117354600559808
893.6600099999999,24.69,-0.08897796,0.2406153,50.0,20.0,3.47827,0.24062348997078006,0.00452810196542508,0.004621406647597944,0.00256725893864973,0.002523986448398494
896.63798,24.79,-0.09100667,0.2401186,50.0,20.0,3.46959,0.24017980356961915,0.004378415336013575,0.004486370202201085,0.0002497353607415209,0.0011808948196469378
899.61301,24.89,-0.09221381,0.2397726,50.0,20.0,3.46095,0.23973601105495068,0.004543732379902465,0.004528671945929409,0.0007956652241428996,0.0006185033546230789
902.58799,24.99,-0.09020168,0.2392431,50.0,20.0,3.45233,0.23927424401042122,0.004639666962736655,0.0045917167947180145,0.00028906387924068633,0.0005071174333030096
905.5630199999999,25.09,-0.08638051,0.23878990000000003,50.0,20.0,3.44375,0.23881245061744194,0.004603060610707033,0.00457572991493678,0.0005898391008176129,0.0006837064762090425
908.54099,25.19,-0.08256122,0.2383464,50.0,20.0,3.43518,0.23835532025255599,0.0045099859116479735,0.0044813063841262855,0.0012364361742997487,0.0010031404545960988
911.52,25.29,-0.07906651,0.23794630000000003,50.0,20.0,3.42664,0.2379136224584574,0.004329030400517908,0.004349819368807304,0.001238958081157343,0.0009788862046701556
914.4939899999999,25.39,-0.07635143,0.2373955,50.0,20.0,3.41814,0.23748784297221545,0.00420005653026756,0.004261500510441898,0.00045447882953267293,0.0006544266438428352
917.47397,25.49,-0.07411989,0.23706119999999997,50.0,20.0,3.40965,0.23706699222328145,0.004256930233955458,0.004243031313272627,0.00016789193814895076,0.0007372696305426172
920.45402,25.59,-0.07187664,0.23660799999999998,50.0,20.0,3.40119,0.23663668837589463,0.0042976328230714955,0.0041652009913570225,0.0016316747775399487,0.0014515167553063404
923.439,25.69,-0.06712301,0.2361645,50.0,20.0,3.39274,0.2362214172101394,0.0039406470400020766,0.0039280312714894735,0.002695461731659854,0.001806959670896498
926.42698,25.79,-0.06075509,0.23577510000000002,50.0,20.0,3.3843,0.23585254407112569,0.0035003755257516644,0.0037407839695826916,0.0005694295885303458,0.0013825750345889396
929.4150099999999,25.89,-0.05457331,0.2356349,50.0,20.0,3.3759,0.23549370872401246,0.0038150435672186234,0.0038118248758376634,0.0014444658524498943,0.00099968253640829
932.408,25.99,-0.04938945,0.23498650000000001,50.0,20.0,3.36751,0.23508990983561245,0.004115507882735514,0.003894806576506377,0.00022034696779818508,0.0008944380453399616
935.4040299999999,26.09,-0.04540848,0.2346406,50.0,20.0,3.35913,0.23469801187825787,0.0036890060960104165,0.0037917198948815333,0.0013058849799141015,0.0008002072333524487
938.39902,26.19,-0.04107723,0.2343923,50.0,20.0,3.35079,0.2343371330107985,0.0036385789372843647,0.0037181100987444303,0.00011880858873844491,0.0006959577746267533
941.39701,26.29,-0.0368565,0.23393809999999998,50.0,20.0,3.34246,0.23396133487412576,0.0038436703616770984,0.0036996363625449707,0.0007681006625833431,0.0012653411154154484
944.3979899999999,26.39,-0.03305674,0.2335062,50.0,20.0,3.33415,0.23358414947055742,0.003608664057082933,0.0035075021972918665,0.0029974458876230736,0.002269814953898473
947.4040299999999,26.49,-0.03116639,0.23318339999999999,50.0,20.0,3.32585,0.23324997875770415,0.0030786835689049497,0.003176865088599456,0.0030711554101093552,0.002324627319086589
950.40702,26.59,-0.0302885,0.2330423,50.0,20.0,3.31758,0.23295771280296812,0.0028448246661376686,0.0029760679434439378,0.0007518220434960532,0.0014944641160793066
953.4150099999999,26.69,-0.03116603,0.23261040000000002,50.0,20.0,3.30933,0.2326693178871242,0.002960678036183495,0.0030125860447562203,0.0011915376592629146,0.0010001075625657538
956.42899,26.79,-0.03215954,0.2323408,50.0,20.0,3.30108,0.23236032869840356,0.0032254241478444357,0.00313772003123356,0.0009218262983353431,0.00080610892120371
959.4380199999999,26.89,-0.03434424,0.2320055,50.0,20.0,3.29287,0.23203336420258455,0.0032264423100496487,0.0031570121863907603,0.0004892415655537441,0.0006873500522604336
962.45103,26.99,-0.03712326,0.2317137,50.0,20.0,3.28468,0.23172328749084395,0.0030148090397990046,0.0030796697713107025,0.000861021034428977,0.0008044186517634848
965.45798,27.09,-0.0399157,0.2314431,50.0,20.0,3.27653,0.23141935322637466,0.0030632485925945474,0.002991195231477373,0.0009896402465444099,0.0009249706002117323
968.47501,27.19,-0.04269955,0.2310334,50.0,20.0,3.26837,0.23112194760640387,0.002840825591240659,0.0028814733270900983,0.0010586956614186127,0.0007957560173079433
971.48698,27.29,-0.04468275,0.23088170000000002,50.0,20.0,3.26025,0.2308455274199844,0.0027543529874058947,0.0028152284018120814,0.00017830112690583877,0.00047679569893838586
974.49698,27.39,-0.0472195,0.230558,50.0,20.0,3.25216,0.23056508339878867,0.0028456484342829214,0.0028278058202277257,0.00019293909800222053,0.0005052799824102964
977.50901,27.49,-0.04922325,0.2303415,50.0,20.0,3.24408,0.23027813842465203,0.0028893831623939548,0.002798651451688178,0.0010378789371646158,0.0012341253609823447
980.51902,27.59,-0.05305908,0.2299521,50.0,20.0,3.23604,0.22999449533261687,0.002700630099084833,0.0026000229462970377,0.0027798330277687966,0.001985159763111967
983.525,27.69,-0.05675359,0.2296284,50.0,20.0,3.22802,0.2297512533575959,0.002171012208187051,0.002325813684320049,0.002146021070523335,0.0017844382726248961
986.53202,27.79,-0.06115297,0.2296284,50.0,20.0,3.22003,0.22954262786425578,0.0021187060857990048,0.0022406703724728934,0.00044533957348136255,0.0012051827876189572
989.5350099999999,27.89,-0.06621624,0.2292177,50.0,20.0,3.21207,0.22931591792327197,0.002407640482349649,0.002354518517417445,0.0013895007981484797,0.0009606494199859787
992.53702,27.99,-0.07141919,0.2290786,50.0,20.0,3.20413,0.2290684442410561,0.002503225873207171,0.002456629440997549,0.0005237725223449508,0.0006800849728953277
995.538,28.09,-0.07664739,0.2288399,50.0,20.0,3.19622,0.22881885614067207,0.0024864949180720686,0.00246034206545954,0.00037982072169988335,0.0004959584993457938
998.53702,28.19,-0.08180838,0.228549,50.0,20.0,3.18833,0.2285728981571969,0.002409464372593817,0.0023991601708952402,0.0007092942272749342,0.00047757956264799656
1001.53,28.29,-0.08720259,0.2284186,50.0,20.0,3.18048,0.22833933185831054,0.00228124629082771,0.0023501954687982917,0.0001363856306479394,0.0003777676211038299
1004.5279899999999,28.39,-0.09253034,0.22814900000000002,50.0,20.0,3.17264,0.22810850459425985,0.0023728564773204397,0.0023721746799328027,0.000432320492296856,0.00027923719720483297
1007.52402,28.49,-0.09825642,0.2278572,50.0,20.0,3.16482,0.22786480531905068,0.002459574685467203,0.0024030961354251754,9.976826598283306e-05,0.00019695120161427855
1010.5169999999999,28.59,-0.10429,0.2275982,50.0,20.0,3.15703,0.22762470428052553,0.002344736687478033,0.0024006628283791877,6.901021268118646e-05,0.00027730765277375835
1013.512,28.69,-0.10996,0.2274465,50.0,20.0,3.14926,0.22738636084835553,0.00245851958388954,0.00237831494246466,0.0005776691353312075,0.0007301673958811205
1016.50901,28.79,-0.11508,0.2270899,50.0,20.0,3.14149,0.22714207367101497,0.0023251679924367608,0.0022589658308597373,0.001711413928963193,0.0011541885076677486
1019.50199,28.89,-0.12064,0.2269276,50.0,20.0,3.13376,0.22693029416579866,0.001961068986327419,0.002099563051700268,0.0011103218108531876,0.000941361731811217
1022.49601,28.99,-0.12603,0.2267556,50.0,20.0,3.12604,0.22673234900682895,0.0020561325748644776,0.0020601262693365355,0.00015404344414773896,0.0004220033340421393
1025.4859999999999,29.09,-0.13109,0.2265179,50.0,20.0,3.11836,0.2265209162403443,0.0021260207472657555,0.002079706988386732,6.220320070406127e-05,0.00015165494693145023
1028.48099,29.19,-0.13668,0.22636710000000002,50.0,20.0,3.11067,0.2263127418262725,0.0020396907123174657,0.0020733377205017097,8.103685282953577e-05,0.00010395796504862434
1031.47501,29.29,-0.1426,0.2260859,50.0,20.0,3.10301,0.2261083535306028,0.0020775415395899444,0.002071327114149939,4.914850434875606e-05,0.00024402084583428766
1034.47098,29.39,-0.14907,0.2259564,50.0,20.0,3.09536,0.22589680913836319,0.002113729801038744,0.002035759304306438,0.0007258745560477647,0.0005113443846892778
1037.46702,29.49,-0.1557,0.22567530000000002,50.0,20.0,3.08773,0.22569582673888167,0.0018834975755144256,0.001956457240043799,0.0005056796795712276,0.0008074266458810731
1040.47098,29.59,-0.16135,0.22554580000000002,50.0,20.0,3.08009,0.22551285614064479,0.0018565427665553358,0.0020003558253072844,0.0015118040485383177,0.0012906841629458645
1043.47202,29.69,-0.1683,0.2254153,50.0,20.0,3.07248,0.225309030907157,0.0022676450442027374,0.0022121803561852105,0.0021631196513016704,0.0015804509159608481
1046.48099,29.79,-0.17168,0.2250162,50.0,20.0,3.06487,0.2250640587636671,0.0025324361182139654,0.0023146979228099262,0.0005311366433455728,0.0018248855661246685
1049.48502,29.89,-0.17678,0.22476790000000002,50.0,20.0,3.05728,0.22482527150659087,0.002161007289116057,0.0021038037297181735,0.0032998266291855843,0.002431954148933062
1052.4960099999998,29.99,-0.18234,0.2245949,50.0,20.0,3.04969,0.22463605352728835,0.0016501562339676923,0.0017663105863235766,0.0028877814862585394,0.0022580223633051357
1055.5030299999999,30.09,-0.18852,0.2244867,50.0,20.0,3.04213,0.22448367897418348,0.0014770832190080796,0.0015887733058953684,0.000642998845216125,0.001209971311379543
1058.5079700000001,30.19,-0.19647,0.2243244,50.0,20.0,3.03459,0.2243294541141722,0.001618135782958774,0.0015959043813147332,0.00045954081710962436,0.00048469823404623886
1061.51798,30.29,-0.20336,0.2241958,50.0,20.0,3.02705,0.22416421080345914,0.0016617086280454885,0.001632533931582549,0.00018060076467117658,0.0002771125609139776
1064.5240199999998,30.39,-0.20939,0.2240325,50.0,20.0,3.01954,0.2239999286609208,0.0016164497998598648,0.0016438356310955328,0.00019134223991543187,0.0003121082000572974
1067.533,30.49,-0.21652,0.2238064,50.0,20.0,3.01203,0.2238385749478485,0.0016497765781000595,0.0016882287934425334,0.0006490813888023195,0.0004338905826971066
1070.538,30.59,-0.22098,0.2236663,50.0,20.0,3.00455,0.22366399510059407,0.0018272615485415145,0.0017367620409124384,7.954569814860868e-05,0.0005537383880344528
1073.54398,30.69,-0.22613,0.2234064,50.0,20.0,2.99708,0.22348381316533558,0.0017217195857224254,0.0016827049470646094,0.0010602046471420018,0.0007095994104510872
1076.54801,30.79,-0.23133,0.2232769,50.0,20.0,2.98963,0.22332315752995313,0.001503953852717288,0.0015771392531977926,0.0007353222614575883,0.0006323332476038859
1079.55198,30.89,-0.23703,0.2232121,50.0,20.0,2.98219,0.22317616795357345,0.0014966089721983877,0.0015615740279439083,0.0002568460268889128,0.0006245638501334921
1082.55997,30.99,-0.24416,0.223017,50.0,20.0,2.97475,0.22301370989511202,0.001740170722516865,0.0015441157037953805,0.001100086334289277,0.0013219186345725927
1085.56498,31.09,-0.25111,0.2227474,50.0,20.0,2.96734,0.2228502944525149,0.0013713856903301291,0.0013159469723394857,0.0030693394353654563,0.001948073508172363
1088.56998,31.19,-0.25881,0.2227474,50.0,20.0,2.95994,0.2227477454253093,0.0008001589773076745,0.0010646065762596822,0.0013675431441968824,0.0015118332137885402
1091.5740099999998,31.29,-0.26692,0.2226826,50.0,20.0,2.95255,0.22265727676133532,0.0010972716990949039,0.0010540168306719842,0.0007328130604384378,0.000859405493783383
1094.5790200000001,31.39,-0.2751,0.222586,50.0,20.0,2.94517,0.22253807918893814,0.001174753599203271,0.0011264750294248678,0.0005713838696685819,0.0007282256595085927
1097.585,31.49,-0.28277,0.22235890000000003,50.0,20.0,2.9378,0.22242919328653843,0.001073164801251636,0.001196117011611491,0.000986927531771778,0.0007901629322148928
1100.59397,31.59,-0.28116,0.22235890000000003,50.0,20.0,2.93044,0.22230550148824085,0.0014250890407510042,0.0012997156373920843,0.000715449403058413,0.0007133841205434708
1103.603,31.69,-0.28457,0.22209990000000002,50.0,20.0,2.92309,0.22215997250608116,0.0013633468564933082,0.0012916018918441882,0.000768304527334146,0.0006114226174991751
1106.60599,31.79,-0.29135,0.22209900000000002,50.0,20.0,2.91576,0.22204142189449425,0.00106483011829539,0.0012281443067268536,3.275466678629574e-05,0.0006800998987175306
1109.6069699999998,31.89,-0.29883,0.22196950000000001,50.0,20.0,2.90845,0.22192754727185016,0.0012963063935256258,0.0013069623937307267,0.001272401539390705,0.0009488452583720273
1112.6109999999999,31.99,-0.3073,0.2217753,50.0,20.0,2.90114,0.2217806425879332,0.0015676510833415591,0.0013689239754112593,0.0006053359461497265,0.0017557915225484995
1115.6139899999998,32.09,-0.31496,0.2216458,50.0,20.0,2.89385,0.2216345959803943,0.0012627099642603667,0.0011363486512172062,0.0039053680561663418,0.0030317122967505154
1118.6119800000001,32.19,-0.33107,0.2214506,50.0,20.0,2.88658,0.22153876132909536,0.0006237296535527292,0.0006838822123795502,0.0043901010791925,0.003272753582597072
1121.61503,32.29,-0.33793,0.2214506,50.0,20.0,2.8793,0.221507194899239,0.00010010646841962512,0.00041049324211403835,0.0004918528318331832,0.002667033812875237
1124.61698,32.39,-0.34566,0.2215482,50.0,20.0,2.87204,0.2214868827477326,0.00047549551062786577,0.0005975022658397785,0.0036844293538708765,0.002669569757990777
1127.61899,32.49,-0.35346,0.22145150000000002,50.0,20.0,2.86478,0.2213994699937984,0.0012067571390677045,0.0009706147504630944,0.0028696135470563863,0.0023065837128387998
1130.616,32.59,-0.36137,0.22119260000000002,50.0,20.0,2.85755,0.22127240506200313,0.0011999997531972895,0.0010866522251208426,0.00042251269927902346,0.0014781317537763089
1133.61002,32.69,-0.36958,0.22119260000000002,50.0,20.0,2.85033,0.2211691214721501,0.000903126008401145,0.0009702614058607028,0.0014625542396897867,0.0012613912736506039
1136.6069699999998,32.79,-0.37817,0.22115970000000001,50.0,20.0,2.84312,0.22108118576017016,0.0008705070581207508,0.0008316076066292858,0.0013325456337138636,0.001235469731647641
1139.60502,32.89,-0.38654,0.2209326,50.0,20.0,2.8359,0.2210016690401252,0.0006804406039808697,0.0007030776471207966,0.001088712653013288,0.0010484294114708793
1142.6039799999999,32.99,-0.39339,0.2209326,50.0,20.0,2.8287,0.22094379064756228,0.000527024565570855,0.0006679469550222994,0.0006401704503741154,0.0011247241519894103
1145.60099,33.09,-0.40223,0.2208998,50.0,20.0,2.82151,0.2208823047576739,0.0007844783505763786,0.0008261077699794606,0.002134622008357158,0.0013677037027400437
1148.60001,33.19,-0.4118,0.2208032,50.0,20.0,2.81432,0.2207796641948765,0.0012087133409917072,0.0009782890816825607,0.0003624251676481102,0.0013819738231530716
1151.59598,33.29,-0.42175,0.22066210000000003,50.0,20.0,2.80714,0.2206674612593527,0.0009106490674888335,0.0008741649205960688,0.0020878117770870563,0.0014726346591507514
1154.59397,33.39,-0.43118,0.22066299999999997,50.0,20.0,2.79997,0.22059928528757416,0.0005365355402382477,0.0006709337935331629,0.0015003469952634824,0.0012043326464076928
1157.59299,33.49,-0.43062,0.22053360000000002,50.0,20.0,2.7928,0.22054485707724578,0.0005887461265441374,0.0005989220646195981,0.000123757675282464,0.0005365885956477489
1160.59598,33.59,-0.43745,0.22053360000000002,50.0,20.0,2.78563,0.22048213159162453,0.0006352764965047442,0.0005968642029151602,8.426181700529195e-05,0.000212255529960139
1163.598,33.69,-0.44616,0.22040310000000002,50.0,20.0,2.77847,0.22042307883320855,0.0005487656150879872,0.000577351212417861,0.00025945593367790107,0.0002851758605331295
1166.59897,33.79,-0.45535,0.22040310000000002,50.0,20.0,2.77131,0.22036713639677646,0.0005826212108921425,0.0005449793790849357,0.00044908107429314156,0.0005211398115285114
1169.60203,33.89,-0.46456,0.2202736,50.0,20.0,2.76416,0.22031173425574832,0.0004880648271932131,0.00047764487585973456,0.0008914051217202568,0.0008158362304578895
1172.3069799999998,33.98,-0.47302,0.2202736,50.0,20.0,2.75772,0.2202736,0.0003876761306310311,0.00038767613063103094,0.0010519273885668096,0.0010519273885668096