File: kk_manual/PYRO_MDF_30_900_N2_10Kmin_01.txt
#EXPORTTYPE:                 ,DATA ALL
#FILE:                       ,PYRO_MDF_30_900_N2_10Kmin_01.ngb-ds3
#FORMAT:                     ,NETZSCH5
#FTYPE:                      ,ANSI
#IDENTITY:                   ,PYRO_MDF_10Kmin_01
#DECIMAL:                    ,POINT
#SEPARATOR:                  ,COMMA
#MTYPE:                      ,DSC
#INSTRUMENT:                 ,NETZSCH STA 449F3
#PROJECT:                    ,PYROBOARD
#DATE/TIME:                  ,23.09.2020 5:12:42 (UTC+2)
#CORR. FILE:                 ,Correction for method PYROBOARD_30_900_N2_10Kmin
#TEMPCAL:                    ,11-03-2020 14:48
#SENSITIVITY:                ,11-03-2020 15:30
#LABORATORY:                 ,TUPO
#OPERATOR:                   ,LH
#REMARK:                     ,
#SAMPLE:                     ,PYRO_MDF_10Kmin_01
#SAMPLE MASS /mg:            ,9.8914
#MATERIAL:                   ,MDF
#REFERENCE:                  ,-----
#REFERENCE MASS /mg:         ,0
#TYPE OF CRUCIBLE:           ,Al2O3 85 µl, open
#SAMPLE CRUCIBLE MASS /mg:   ,136.8905
#REFERENCE CRUCIBLE MASS /mg:,132.37
#DSC RANGE /µV:              ,5000
#TG RANGE /mg:               ,35000
#TAU-R:                      ,---
#CORR. CODE:                 ,020
#EXO:                        ,-1
#RANGE:                      ,30°C/10.0(K/min)/900°C
#SEGMENT:                    ,S2/3
#SEG. 2:                     ,30°C/10.0(K/min)/900°C

##Temp./°C,Time/min,DSC/(mW/mg),Mass/%,Gas Flow(purge2)/(ml/min),Gas Flow(protective)/(ml/min),Sensit./(uV/mW)
 30.01800, 4.99000,-1.825111e-02,100.10848,50.00000,20.00000,4.80935
 30.01700, 5.12000,-1.815494e-02,100.11303,50.00000,20.00000,4.80934
 30.03400, 5.25000,-1.751252e-02,100.12880,50.00000,20.00000,4.80958
 30.08300, 5.38000,-1.545749e-02,100.12890,50.00000,20.00000,4.81029
 30.19600, 5.51000,-1.146095e-02,100.11869,50.00000,20.00000,4.81193
 30.40400, 5.64000,-4.885884e-03,100.12435,50.00000,20.00000,4.81493
 30.71400, 5.77000, 4.705306e-03,100.14245,50.00000,20.00000,4.81940
 31.15700, 5.90000, 1.708620e-02,100.12546,50.00000,20.00000,4.82576
 31.75200, 6.03000, 3.224556e-02,100.11636,50.00000,20.00000,4.83426
 32.50000, 6.16000, 4.989419e-02,100.12203,50.00000,20.00000,4.84487
 33.41600, 6.29000, 6.925997e-02,100.13456,50.00000,20.00000,4.85777
 34.50100, 6.42000, 9.071455e-02,100.14922,50.00000,20.00000,4.87289
 35.74500, 6.55000,      0.11283,100.13668,50.00000,20.00000,4.89003
 37.13700, 6.68000,      0.13533,100.11869,50.00000,20.00000,4.90895
 38.66300, 6.81000,      0.15804,100.11080,50.00000,20.00000,4.92939
 40.31200, 6.94000,      0.18060,100.11080,50.00000,20.00000,4.95111
 42.05800, 7.07000,      0.20264,100.11192,50.00000,20.00000,4.97370
 43.87600, 7.20000,      0.22403,100.08705,50.00000,20.00000,4.99676
 45.75500, 7.33000,      0.24466,100.06895,50.00000,20.00000,5.02012
 47.67200, 7.46000,      0.26442,100.05429,50.00000,20.00000,5.04345
 49.60600, 7.59000,      0.28306,100.02376,50.00000,20.00000,5.06646
 51.54500, 7.72000,      0.30054, 99.99879,50.00000,20.00000,5.08901
 53.47600, 7.85000,      0.31701, 99.96492,50.00000,20.00000,5.11095
 55.38100, 7.98000,      0.33188, 99.93550,50.00000,20.00000,5.13208
 57.25300, 8.11000,      0.34556, 99.91528,50.00000,20.00000,5.15236
 59.09000, 8.24000,      0.35758, 99.87454,50.00000,20.00000,5.17178
 60.87700, 8.37000,      0.36812, 99.83379,50.00000,20.00000,5.19023
 62.62100, 8.50000,      0.37760, 99.79315,50.00000,20.00000,5.20780
 64.31400, 8.63000,      0.38568, 99.71743,50.00000,20.00000,5.22446
 65.95800, 8.76000,      0.39293, 99.65758,50.00000,20.00000,5.24026
 67.55400, 8.89000,      0.39862, 99.62139,50.00000,20.00000,5.25524
 69.10700, 9.02000,      0.40333, 99.55921,50.00000,20.00000,5.26948
 70.62000, 9.15000,      0.40681, 99.49370,50.00000,20.00000,5.28304
 72.09200, 9.28000,      0.40897, 99.41565,50.00000,20.00000,5.29592
 73.53000, 9.41000,      0.40984, 99.36035,50.00000,20.00000,5.30822
 74.94300, 9.54000,      0.40935, 99.30273,50.00000,20.00000,5.32003
 76.32500, 9.67000,      0.40758, 99.25187,50.00000,20.00000,5.33132
 77.68800, 9.80000,      0.40469, 99.16139,50.00000,20.00000,5.34220
 79.03100, 9.93000,      0.40024, 99.11620,50.00000,20.00000,5.35267
 80.36200,10.06000,      0.39473, 99.05847,50.00000,20.00000,5.36281
 81.68500,10.19000,      0.38853, 99.01551,50.00000,20.00000,5.37264
 82.99200,10.32000,      0.38144, 98.95232,50.00000,20.00000,5.38213
 84.29300,10.45000,      0.37365, 98.90258,50.00000,20.00000,5.39134
 85.59300,10.58000,      0.36511, 98.83252,50.00000,20.00000,5.40032
 86.88600,10.71000,      0.35628, 98.79188,50.00000,20.00000,5.40902
 88.17500,10.84000,      0.34684, 98.75447,50.00000,20.00000,5.41748
 89.46800,10.97000,      0.33746, 98.72283,50.00000,20.00000,5.42574
 90.75800,11.10000,      0.32790, 98.66753,50.00000,20.00000,5.43375
 92.04500,11.23000,      0.31802, 98.64043,50.00000,20.00000,5.44153
 93.33700,11.36000,      0.30851, 98.58604,50.00000,20.00000,5.44912
 94.63000,11.49000,      0.29875, 98.57249,50.00000,20.00000,5.45649
 95.91800,11.62000,      0.28929, 98.52397,50.00000,20.00000,5.46361
 97.21100,11.75000,      0.28004, 98.49000,50.00000,20.00000,5.47054
 98.50000,11.88000,      0.27113, 98.46290,50.00000,20.00000,5.47724
 99.79000,12.01000,      0.26256, 98.44936,50.00000,20.00000,5.48372
101.07800,12.14000,      0.25428, 98.42560,50.00000,20.00000,5.48997
102.36900,12.27000,      0.24648, 98.39507,50.00000,20.00000,5.49603
103.65800,12.40000,      0.23922, 98.38496,50.00000,20.00000,5.50186
104.94700,12.53000,      0.23244, 98.37131,50.00000,20.00000,5.50747
106.23900,12.66000,      0.22622, 98.34078,50.00000,20.00000,5.51289
107.52500,12.79000,      0.22043, 98.33067,50.00000,20.00000,5.51806
108.81600,12.92000,      0.21504, 98.31368,50.00000,20.00000,5.52305
110.10700,13.05000,      0.21024, 98.31378,50.00000,20.00000,5.52782
111.39600,13.18000,      0.20623, 98.30024,50.00000,20.00000,5.53238
112.68700,13.31000,      0.20233, 98.28659,50.00000,20.00000,5.53673
113.97900,13.44000,      0.19936, 98.27304,50.00000,20.00000,5.54088
115.27400,13.57000,      0.19678, 98.25949,50.00000,20.00000,5.54483
116.56800,13.70000,      0.19471, 98.24938,50.00000,20.00000,5.54856
117.86800,13.83000,      0.19319, 98.25272,50.00000,20.00000,5.55211
119.16300,13.96000,      0.19242, 98.23240,50.00000,20.00000,5.55543
120.46200,14.09000,      0.19139, 98.23240,50.00000,20.00000,5.55856
121.75900,14.22000,      0.19068, 98.23240,50.00000,20.00000,5.56148
123.06100,14.35000,      0.19029, 98.21875,50.00000,20.00000,5.56421
124.36100,14.48000,      0.18965, 98.20520,50.00000,20.00000,5.56672
125.66500,14.61000,      0.18946, 98.20520,50.00000,20.00000,5.56904
126.96900,14.74000,      0.18940, 98.19176,50.00000,20.00000,5.57116
128.27299,14.87000,      0.18961, 98.19166,50.00000,20.00000,5.57307
129.57800,15.00000,      0.18973, 98.17811,50.00000,20.00000,5.57478
130.88699,15.13000,      0.19029, 98.17811,50.00000,20.00000,5.57630
132.19299,15.26000,      0.19085, 98.15435,50.00000,20.00000,5.57762
133.50200,15.39000,      0.19152, 98.15102,50.00000,20.00000,5.57873
134.80701,15.52000,      0.19222, 98.15092,50.00000,20.00000,5.57965
136.11501,15.65000,      0.19325, 98.15102,50.00000,20.00000,5.58037
137.42700,15.78000,      0.19435, 98.13403,50.00000,20.00000,5.58090
138.73199,15.91000,      0.19551, 98.13747,50.00000,20.00000,5.58123
140.04401,16.04000,      0.19689, 98.13747,50.00000,20.00000,5.58137
141.35400,16.17000,      0.19857, 98.11027,50.00000,20.00000,5.58132
142.66299,16.30000,      0.20020, 98.10350,50.00000,20.00000,5.58107
143.97099,16.43000,      0.20207, 98.11027,50.00000,20.00000,5.58064
145.28101,16.56000,      0.20389, 98.10684,50.00000,20.00000,5.58001
146.58600,16.69000,      0.20587, 98.08318,50.00000,20.00000,5.57920
147.89400,16.82000,      0.20805, 98.08995,50.00000,20.00000,5.57821
149.20200,16.95000,      0.21026, 98.07297,50.00000,20.00000,5.57703
150.50800,17.08000,      0.21271, 98.05942,50.00000,20.00000,5.57566
151.81200,17.21000,      0.21508, 98.04254,50.00000,20.00000,5.57412
153.11400,17.34000,      0.21774, 98.04254,50.00000,20.00000,5.57241
154.41701,17.47000,      0.22049, 98.04254,50.00000,20.00000,5.57051
155.72301,17.60000,      0.22350, 98.02889,50.00000,20.00000,5.56843
157.02299,17.73000,      0.22645, 98.00180,50.00000,20.00000,5.56619
158.32401,17.86000,      0.22991, 97.98825,50.00000,20.00000,5.56377
159.61900,17.99000,      0.23313, 97.97470,50.00000,20.00000,5.56119
160.91901,18.12000,      0.23686, 97.96115,50.00000,20.00000,5.55843
162.21500,18.25000,      0.24058, 97.94761,50.00000,20.00000,5.55551
163.51401,18.38000,      0.24451, 97.90686,50.00000,20.00000,5.55242
164.81000,18.51000,      0.24885, 97.90686,50.00000,20.00000,5.54917
166.10600,18.64000,      0.25332, 97.87977,50.00000,20.00000,5.54576
167.39900,18.77000,      0.25807, 97.87977,50.00000,20.00000,5.54219
168.70000,18.90000,      0.26313, 97.85268,50.00000,20.00000,5.53844
169.99300,19.03000,      0.26844, 97.82548,50.00000,20.00000,5.53455
171.28799,19.16000,      0.27386, 97.80516,50.00000,20.00000,5.53050
172.58400,19.29000,      0.27958, 97.77119,50.00000,20.00000,5.52628
173.88200,19.42000,      0.28540, 97.73732,50.00000,20.00000,5.52191
175.18100,19.55000,      0.29132, 97.70345,50.00000,20.00000,5.51738
176.47800,19.68000,      0.29748, 97.67636,50.00000,20.00000,5.51270
177.77699,19.81000,      0.30401, 97.64917,50.00000,20.00000,5.50786
179.07300,19.94000,      0.31071, 97.59498,50.00000,20.00000,5.50289
180.37199,20.07000,      0.31776, 97.54291,50.00000,20.00000,5.49775
181.67000,20.20000,      0.32486, 97.51238,50.00000,20.00000,5.49247
182.96600,20.33000,      0.33222, 97.46830,50.00000,20.00000,5.48706
184.26700,20.46000,      0.33992, 97.43100,50.00000,20.00000,5.48148
185.56400,20.59000,      0.34785, 97.37337,50.00000,20.00000,5.47577
186.86200,20.72000,      0.35591, 97.30341,50.00000,20.00000,5.46992
188.15900,20.85000,      0.36416, 97.24578,50.00000,20.00000,5.46393
189.45900,20.98000,      0.37270, 97.20282,50.00000,20.00000,5.45779
190.75400,21.11000,      0.38155, 97.11800,50.00000,20.00000,5.45154
192.05499,21.24000,      0.39035, 97.05582,50.00000,20.00000,5.44513
193.35400,21.37000,      0.39981, 96.99253,50.00000,20.00000,5.43859
194.65300,21.50000,      0.40935, 96.89760,50.00000,20.00000,5.43192
195.95000,21.63000,      0.41909, 96.83998,50.00000,20.00000,5.42513
197.24500,21.76000,      0.42909, 96.75182,50.00000,20.00000,5.41823
198.54700,21.89000,      0.43917, 96.67276,50.00000,20.00000,5.41115
199.84300,22.02000,      0.44913, 96.59138,50.00000,20.00000,5.40399
201.14301,22.15000,      0.45900, 96.48047,50.00000,20.00000,5.39668
202.43900,22.28000,      0.46899, 96.37765,50.00000,20.00000,5.38927
203.73900,22.41000,      0.47859, 96.28050,50.00000,20.00000,5.38172
205.03400,22.54000,      0.48827, 96.19457,50.00000,20.00000,5.37407
206.33200,22.67000,      0.49769, 96.08730,50.00000,20.00000,5.36629
207.62900,22.80000,      0.50673, 95.98438,50.00000,20.00000,5.35841
208.92500,22.93000,      0.51539, 95.85558,50.00000,20.00000,5.35041
210.22301,23.06000,      0.52336, 95.73912,50.00000,20.00000,5.34229
211.51801,23.19000,      0.53091, 95.62498,50.00000,20.00000,5.33408
212.81599,23.32000,      0.53798, 95.50063,50.00000,20.00000,5.32574
214.11301,23.45000,      0.54427, 95.39215,50.00000,20.00000,5.31730
215.41200,23.58000,      0.54970, 95.26001,50.00000,20.00000,5.30874
216.70799,23.71000,      0.55428, 95.13111,50.00000,20.00000,5.30010
218.00900,23.84000,      0.55802, 95.00343,50.00000,20.00000,5.29132
219.30400,23.97000,      0.56119, 94.86775,50.00000,20.00000,5.28248
220.60001,24.10000,      0.56367, 94.74118,50.00000,20.00000,5.27353
221.89999,24.23000,      0.56535, 94.60561,50.00000,20.00000,5.26446
223.19800,24.36000,      0.56640, 94.46993,50.00000,20.00000,5.25530
224.49899,24.49000,      0.56656, 94.33203,50.00000,20.00000,5.24603
225.79700,24.62000,      0.56631, 94.18736,50.00000,20.00000,5.23669
227.09700,24.75000,      0.56550, 94.06301,50.00000,20.00000,5.22724
228.39999,24.88000,      0.56439, 93.92855,50.00000,20.00000,5.21768
229.69501,25.01000,      0.56266, 93.79298,50.00000,20.00000,5.20809
230.99899,25.14000,      0.56056, 93.66640,50.00000,20.00000,5.19835
232.30000,25.27000,      0.55823, 93.51385,50.00000,20.00000,5.18854
233.60100,25.40000,      0.55628, 93.38272,50.00000,20.00000,5.17865
234.90300,25.53000,      0.55403, 93.21763,50.00000,20.00000,5.16868
236.20599,25.66000,      0.55195, 93.10238,50.00000,20.00000,5.15861
237.50600,25.79000,      0.55000, 92.94295,50.00000,20.00000,5.14849
238.80901,25.92000,      0.54820, 92.80747,50.00000,20.00000,5.13827
240.10699,26.05000,      0.54669, 92.66503,50.00000,20.00000,5.12801
241.40601,26.18000,      0.54550, 92.51247,50.00000,20.00000,5.11767
242.70599,26.31000,      0.54438, 92.35880,50.00000,20.00000,5.10725
244.00800,26.44000,      0.54376, 92.18572,50.00000,20.00000,5.09675
245.31000,26.57000,      0.54363, 92.03094,50.00000,20.00000,5.08618
246.61200,26.70000,      0.54344, 91.87272,50.00000,20.00000,5.07554
247.91400,26.83000,      0.54384, 91.72239,50.00000,20.00000,5.06484
249.21400,26.96000,      0.54434, 91.56306,50.00000,20.00000,5.05409
250.51100,27.09000,      0.54501, 91.39018,50.00000,20.00000,5.04330
251.81500,27.22000,      0.54638, 91.21953,50.00000,20.00000,5.03239
253.11501,27.35000,      0.54824, 91.06464,50.00000,20.00000,5.02146
254.41701,27.48000,      0.55034, 90.87589,50.00000,20.00000,5.01046
255.71400,27.61000,      0.55304, 90.70069,50.00000,20.00000,4.99944
257.01300,27.74000,      0.55617, 90.51760,50.00000,20.00000,4.98835
258.31100,27.87000,      0.55972, 90.31197,50.00000,20.00000,4.97722
259.61200,28.00000,      0.56379, 90.11978,50.00000,20.00000,4.96601
260.91000,28.13000,      0.56790, 89.92092,50.00000,20.00000,4.95478
262.20901,28.26000,      0.57246, 89.72307,50.00000,20.00000,4.94350
263.50900,28.39000,      0.57678, 89.51178,50.00000,20.00000,4.93216
264.80600,28.52000,      0.58142, 89.29927,50.00000,20.00000,4.92080
266.10699,28.65000,      0.58628, 89.05967,50.00000,20.00000,4.90937
267.40601,28.78000,      0.59116, 88.82461,50.00000,20.00000,4.89791
268.70700,28.91000,      0.59579, 88.59057,50.00000,20.00000,4.88639
270.00699,29.04000,      0.60078, 88.32842,50.00000,20.00000,4.87485
271.30499,29.17000,      0.60525, 88.07639,50.00000,20.00000,4.86329
272.60300,29.30000,      0.60980, 87.80292,50.00000,20.00000,4.85170
273.90601,29.43000,      0.61402, 87.54289,50.00000,20.00000,4.84003
275.20200,29.56000,      0.61796, 87.24010,50.00000,20.00000,4.82839
276.50201,29.69000,      0.62169, 86.95976,50.00000,20.00000,4.81668
277.80301,29.82000,      0.62507, 86.65798,50.00000,20.00000,4.80494
279.10400,29.95000,      0.62806, 86.33821,50.00000,20.00000,4.79317
280.40302,30.08000,      0.63104, 86.01156,50.00000,20.00000,4.78139
281.70401,30.21000,      0.63370, 85.67591,50.00000,20.00000,4.76958
283.00400,30.34000,      0.63586, 85.35038,50.00000,20.00000,4.75775
284.30301,30.47000,      0.63785, 84.99431,50.00000,20.00000,4.74590
285.60001,30.60000,      0.63982, 84.62591,50.00000,20.00000,4.73406
286.90100,30.73000,      0.64134, 84.23476,50.00000,20.00000,4.72217
288.19901,30.86000,      0.64277, 83.86524,50.00000,20.00000,4.71029
289.49600,30.99000,      0.64393, 83.48431,50.00000,20.00000,4.69840
290.79300,31.12000,      0.64480, 83.07294,50.00000,20.00000,4.68650
292.09100,31.25000,      0.64529, 82.65823,50.00000,20.00000,4.67458
293.38501,31.38000,      0.64560, 82.23322,50.00000,20.00000,4.66268
294.68201,31.51000,      0.64644, 81.81851,50.00000,20.00000,4.65075
295.98001,31.64000,      0.64734, 81.35963,50.00000,20.00000,4.63881
297.27701,31.77000,      0.64846, 80.90863,50.00000,20.00000,4.62687
298.57501,31.90000,      0.64982, 80.44873,50.00000,20.00000,4.61491
299.87299,32.03000,      0.65163, 80.00451,50.00000,20.00000,4.60296
301.16599,32.16000,      0.65334, 79.50610,50.00000,20.00000,4.59105
302.46500,32.29000,      0.65560, 79.03033,50.00000,20.00000,4.57908
303.76401,32.42000,      0.65833, 78.55790,50.00000,20.00000,4.56711
305.06201,32.55000,      0.66128, 78.05038,50.00000,20.00000,4.55516
306.35999,32.68000,      0.66471, 77.55763,50.00000,20.00000,4.54322
307.66101,32.81000,      0.66875, 77.04345,50.00000,20.00000,4.53125
308.95999,32.94000,      0.67298, 76.51905,50.00000,20.00000,4.51930
310.25601,33.07000,      0.67770, 75.98667,50.00000,20.00000,4.50740
311.55499,33.20000,      0.68272, 75.45772,50.00000,20.00000,4.49547
312.85400,33.33000,      0.68753, 74.89824,50.00000,20.00000,4.48356
314.15201,33.46000,      0.69329, 74.36596,50.00000,20.00000,4.47167
315.45200,33.59000,      0.69913, 73.81781,50.00000,20.00000,4.45978
316.75101,33.72000,      0.70516, 73.24590,50.00000,20.00000,4.44791
318.04800,33.85000,      0.71127, 72.68642,50.00000,20.00000,4.43607
319.34799,33.98000,      0.71812, 72.10895,50.00000,20.00000,4.42423
320.64499,34.11000,      0.72460, 71.53026,50.00000,20.00000,4.41243
321.94601,34.24000,      0.73309, 70.94713,50.00000,20.00000,4.40062
323.24701,34.37000,      0.74142, 70.33336,50.00000,20.00000,4.38883
324.54800,34.50000,      0.75013, 69.74113,50.00000,20.00000,4.37706
325.84601,34.63000,      0.75878, 69.13990,50.00000,20.00000,4.36535
327.14999,34.76000,      0.76753, 68.51380,50.00000,20.00000,4.35361
328.45099,34.89000,      0.77613, 67.88992,50.00000,20.00000,4.34192
329.75201,35.02000,      0.78472, 67.26716,50.00000,20.00000,4.33026
331.05499,35.15000,      0.79393, 66.63539,50.00000,20.00000,4.31861
332.35400,35.28000,      0.80285, 65.97987,50.00000,20.00000,4.30703
333.66000,35.41000,      0.81224, 65.31869,50.00000,20.00000,4.29541
334.96500,35.54000,      0.82133, 64.66206,50.00000,20.00000,4.28384
336.26599,35.67000,      0.83105, 63.99077,50.00000,20.00000,4.27235
337.57101,35.80000,      0.84109, 63.30573,50.00000,20.00000,4.26085
338.87500,35.93000,      0.85120, 62.61523,50.00000,20.00000,4.24939
340.17599,36.06000,      0.86197, 61.90774,50.00000,20.00000,4.23800
341.48199,36.19000,      0.87260, 61.19116,50.00000,20.00000,4.22661
342.78500,36.32000,      0.88400, 60.45890,50.00000,20.00000,4.21528
344.08899,36.45000,      0.89498, 59.72534,50.00000,20.00000,4.20399
345.39301,36.58000,      0.90643, 58.98732,50.00000,20.00000,4.19273
346.69299,36.71000,      0.91764, 58.24930,50.00000,20.00000,4.18156
347.99500,36.84000,      0.92873, 57.46610,50.00000,20.00000,4.17041
349.29599,36.97000,      0.94040, 56.67834,50.00000,20.00000,4.15932
350.59900,37.10000,      0.95122, 55.86238,50.00000,20.00000,4.14826
351.89801,37.23000,      0.96182, 55.05541,50.00000,20.00000,4.13727
353.19501,37.36000,      0.97212, 54.21680,50.00000,20.00000,4.12636
354.48999,37.49000,      0.98267, 53.37931,50.00000,20.00000,4.11551
355.78699,37.62000,      0.99247, 52.51350,50.00000,20.00000,4.10469
357.08701,37.75000,      1.00213, 51.64325,50.00000,20.00000,4.09390
358.37701,37.88000,      1.01166, 50.74024,50.00000,20.00000,4.08324
359.67599,38.01000,      1.02094, 49.81570,50.00000,20.00000,4.07257
360.97400,38.14000,      1.02976, 48.90025,50.00000,20.00000,4.06195
362.26801,38.27000,      1.03707, 47.96217,50.00000,20.00000,4.05143
363.56100,38.40000,      1.04345, 47.01285,50.00000,20.00000,4.04097
364.85800,38.53000,      1.04794, 46.03635,50.00000,20.00000,4.03053
366.15601,38.66000,      1.05072, 45.06894,50.00000,20.00000,4.02014
367.45401,38.79000,      1.05193, 44.10820,50.00000,20.00000,4.00981
368.75400,38.92000,      1.04956, 43.14080,50.00000,20.00000,3.99952
370.04901,39.05000,      1.04433, 42.17217,50.00000,20.00000,3.98934
371.34601,39.18000,      1.03463, 41.26917,50.00000,20.00000,3.97920
372.64099,39.31000,      1.02132, 40.35605,50.00000,20.00000,3.96913
373.93701,39.44000,      1.00395, 39.48802,50.00000,20.00000,3.95913
375.22900,39.57000,      0.98368, 38.66751,50.00000,20.00000,3.94921
376.52802,39.70000,      0.96103, 37.92039,50.00000,20.00000,3.93931
377.82300,39.83000,      0.93545, 37.21523,50.00000,20.00000,3.92950
379.12299,39.96000,      0.90971, 36.59702,50.00000,20.00000,3.91972
380.43399,40.09000,      0.88920, 36.04209,50.00000,20.00000,3.90993
381.76199,40.22000,      0.88547, 35.56056,50.00000,20.00000,3.90008
383.11499,40.35000,      0.91727, 35.15141,50.00000,20.00000,3.89012
384.43701,40.48000,      0.90518, 34.78979,50.00000,20.00000,3.88045
385.72501,40.61000,      0.83806, 34.50277,50.00000,20.00000,3.87111
387.00101,40.74000,      0.79612, 34.25073,50.00000,20.00000,3.86192
388.26901,40.87000,      0.76104, 34.04500,50.00000,20.00000,3.85286
389.53000,41.00000,      0.73088, 33.84836,50.00000,20.00000,3.84391
390.79199,41.13000,      0.70908, 33.70480,50.00000,20.00000,3.83503
392.05399,41.26000,      0.68832, 33.56690,50.00000,20.00000,3.82621
393.31799,41.39000,      0.67265, 33.45843,50.00000,20.00000,3.81745
394.58701,41.52000,      0.65997, 33.35217,50.00000,20.00000,3.80873
395.85901,41.65000,      0.65393, 33.23692,50.00000,20.00000,3.80006
397.14200,41.78000,      0.65290, 33.15220,50.00000,20.00000,3.79138
398.42499,41.91000,      0.65291, 33.04817,50.00000,20.00000,3.78279
399.71399,42.04000,      0.65436, 32.94636,50.00000,20.00000,3.77422
401.00699,42.17000,      0.65747, 32.87529,50.00000,20.00000,3.76570
402.30499,42.30000,      0.66101, 32.78370,50.00000,20.00000,3.75723
403.60300,42.43000,      0.66539, 32.69665,50.00000,20.00000,3.74884
404.90601,42.56000,      0.67061, 32.62659,50.00000,20.00000,3.74049
406.21100,42.69000,      0.67579, 32.54066,50.00000,20.00000,3.73221
407.51801,42.82000,      0.68166, 32.47393,50.00000,20.00000,3.72400
408.82401,42.95000,      0.68815, 32.37900,50.00000,20.00000,3.71587
410.13300,43.08000,      0.69474, 32.30105,50.00000,20.00000,3.70781
411.44000,43.21000,      0.70189, 32.21745,50.00000,20.00000,3.69984
412.75101,43.34000,      0.70953, 32.13606,50.00000,20.00000,3.69193
414.06100,43.47000,      0.71793, 32.06600,50.00000,20.00000,3.68411
415.37100,43.60000,      0.72682, 31.95641,50.00000,20.00000,3.67637
416.67599,43.73000,      0.73561, 31.90667,50.00000,20.00000,3.66875
417.98199,43.86000,      0.74547, 31.82640,50.00000,20.00000,3.66120
419.28699,43.99000,      0.75545, 31.75512,50.00000,20.00000,3.65374
420.58899,44.12000,      0.76633, 31.67263,50.00000,20.00000,3.64639
421.89401,44.25000,      0.77746, 31.60712,50.00000,20.00000,3.63910
423.19501,44.38000,      0.78917, 31.53817,50.00000,20.00000,3.63192
424.49899,44.51000,      0.80151, 31.45688,50.00000,20.00000,3.62480
425.79700,44.64000,      0.81381, 31.39471,50.00000,20.00000,3.61780
427.09799,44.77000,      0.82656, 31.32232,50.00000,20.00000,3.61088
428.39401,44.90000,      0.83973, 31.24438,50.00000,20.00000,3.60406
429.69199,45.03000,      0.85283, 31.18109,50.00000,20.00000,3.59732
430.98801,45.16000,      0.86668, 31.12447,50.00000,20.00000,3.59067
432.28201,45.29000,      0.88023, 31.04996,50.00000,20.00000,3.58412
433.58301,45.42000,      0.89410, 30.98102,50.00000,20.00000,3.57762
434.88000,45.55000,      0.90878, 30.92450,50.00000,20.00000,3.57122
436.17499,45.68000,      0.92316, 30.86344,50.00000,20.00000,3.56492
437.47101,45.81000,      0.93780, 30.79227,50.00000,20.00000,3.55871
438.76901,45.94000,      0.95242, 30.71877,50.00000,20.00000,3.55256
440.06601,46.07000,      0.96705, 30.65892,50.00000,20.00000,3.54651
441.36401,46.20000,      0.98206, 30.60352,50.00000,20.00000,3.54055
442.66400,46.33000,      0.99668, 30.52890,50.00000,20.00000,3.53466
443.96301,46.46000,      1.01161, 30.48028,50.00000,20.00000,3.52886
445.26199,46.59000,      1.02680, 30.42265,50.00000,20.00000,3.52315
446.56201,46.72000,      1.04193, 30.35370,50.00000,20.00000,3.51752
447.85800,46.85000,      1.05727, 30.30851,50.00000,20.00000,3.51199
449.16000,46.98000,      1.07214, 30.24411,50.00000,20.00000,3.50653
450.45901,47.11000,      1.08808, 30.18082,50.00000,20.00000,3.50117
451.76099,47.24000,      1.10384, 30.12542,50.00000,20.00000,3.49588
453.05701,47.37000,      1.11933, 30.08589,50.00000,20.00000,3.49070
454.35300,47.50000,      1.13526, 30.01128,50.00000,20.00000,3.48561
455.65201,47.63000,      1.15095, 29.95032,50.00000,20.00000,3.48060
456.94800,47.76000,      1.16667, 29.90169,50.00000,20.00000,3.47569
458.24600,47.89000,      1.18178, 29.85195,50.00000,20.00000,3.47085
459.54199,48.02000,      1.19724, 29.78644,50.00000,20.00000,3.46611
460.84201,48.15000,      1.21240, 29.72538,50.00000,20.00000,3.46144
462.14200,48.28000,      1.22800, 29.66431,50.00000,20.00000,3.45686
463.44400,48.41000,      1.24339, 29.60558,50.00000,20.00000,3.45235
464.74500,48.54000,      1.25849, 29.55129,50.00000,20.00000,3.44794
466.04300,48.67000,      1.27386, 29.49032,50.00000,20.00000,3.44363
467.34698,48.80000,      1.28925, 29.44736,50.00000,20.00000,3.43938
468.64600,48.93000,      1.30396, 29.40894,50.00000,20.00000,3.43524
469.95099,49.06000,      1.31945, 29.34788,50.00000,20.00000,3.43116
471.25101,49.19000,      1.33494, 29.28570,50.00000,20.00000,3.42718
472.55499,49.32000,      1.35031, 29.23485,50.00000,20.00000,3.42328
473.85699,49.45000,      1.36589, 29.19754,50.00000,20.00000,3.41947
475.15900,49.58000,      1.38143, 29.12293,50.00000,20.00000,3.41575
476.46100,49.71000,      1.39671, 29.08118,50.00000,20.00000,3.41211
477.76401,49.84000,      1.41229, 29.02123,50.00000,20.00000,3.40856
479.06500,49.97000,      1.42829, 28.98392,50.00000,20.00000,3.40510
480.36700,50.10000,      1.44354, 28.92630,50.00000,20.00000,3.40171
481.66699,50.23000,      1.45949, 28.86534,50.00000,20.00000,3.39842
482.96899,50.36000,      1.47545, 28.83592,50.00000,20.00000,3.39521
484.26801,50.49000,      1.49182, 28.76019,50.00000,20.00000,3.39209
485.56601,50.62000,      1.50800, 28.70479,50.00000,20.00000,3.38905
486.86600,50.75000,      1.52448, 28.66526,50.00000,20.00000,3.38609
488.15900,50.88000,      1.54009, 28.61330,50.00000,20.00000,3.38324
489.46100,51.01000,      1.55635, 28.57144,50.00000,20.00000,3.38044
490.75900,51.14000,      1.57231, 28.51159,50.00000,20.00000,3.37773
492.05701,51.27000,      1.58797, 28.46751,50.00000,20.00000,3.37511
493.35599,51.40000,      1.60387, 28.40301,50.00000,20.00000,3.37257
494.65701,51.53000,      1.61944, 28.36227,50.00000,20.00000,3.37010
495.96100,51.66000,      1.63544, 28.31941,50.00000,20.00000,3.36771
497.26300,51.79000,      1.65155, 28.25612,50.00000,20.00000,3.36540
498.56500,51.92000,      1.66732, 28.20527,50.00000,20.00000,3.36318
499.86700,52.05000,      1.68330, 28.16230,50.00000,20.00000,3.36103
501.17001,52.18000,      1.69974, 28.12044,50.00000,20.00000,3.35896
502.47101,52.31000,      1.71594, 28.06737,50.00000,20.00000,3.35697
503.77701,52.44000,      1.73239, 28.00176,50.00000,20.00000,3.35506
505.07999,52.57000,      1.74831, 27.94979,50.00000,20.00000,3.35323
506.38400,52.70000,      1.76492, 27.90682,50.00000,20.00000,3.35147
507.69101,52.83000,      1.78126, 27.85941,50.00000,20.00000,3.34979
508.99799,52.96000,      1.79787, 27.80967,50.00000,20.00000,3.34819
510.30200,53.09000,      1.81450, 27.76670,50.00000,20.00000,3.34666
511.60599,53.22000,      1.83147, 27.71696,50.00000,20.00000,3.34522
512.90997,53.35000,      1.84841, 27.66389,50.00000,20.00000,3.34385
514.21198,53.48000,      1.86500, 27.61981,50.00000,20.00000,3.34255
515.51703,53.61000,      1.86952, 27.57684,50.00000,20.00000,3.34133
516.82001,53.74000,      1.88836, 27.52599,50.00000,20.00000,3.34018
518.12701,53.87000,      1.90610, 27.47291,50.00000,20.00000,3.33910
519.42700,54.00000,      1.92290, 27.43106,50.00000,20.00000,3.33811
520.72900,54.13000,      1.93984, 27.38132,50.00000,20.00000,3.33718
522.03400,54.26000,      1.95678, 27.33390,50.00000,20.00000,3.33632
523.33502,54.39000,      1.97238, 27.28638,50.00000,20.00000,3.33554
524.63501,54.52000,      1.98883, 27.24352,50.00000,20.00000,3.33482
525.93103,54.65000,      2.00670, 27.18468,50.00000,20.00000,3.33418
527.22998,54.78000,      2.02325, 27.12483,50.00000,20.00000,3.33361
528.53101,54.91000,      2.04042, 27.08075,50.00000,20.00000,3.33310
529.82898,55.04000,      2.05715, 27.02879,50.00000,20.00000,3.33266
531.13098,55.17000,      2.07356, 27.00382,50.00000,20.00000,3.33229
532.42798,55.30000,      2.09009, 26.96196,50.00000,20.00000,3.33199
533.72699,55.43000,      2.10633, 26.89311,50.00000,20.00000,3.33175
535.02600,55.56000,      2.12266, 26.84782,50.00000,20.00000,3.33158
536.31897,55.69000,      2.13871, 26.79020,50.00000,20.00000,3.33147
537.61902,55.82000,      2.15501, 26.76310,50.00000,20.00000,3.33143
538.91400,55.95000,      2.17132, 26.71336,50.00000,20.00000,3.33145
540.21002,56.08000,      2.17844, 26.64896,50.00000,20.00000,3.33153
541.50897,56.21000,      2.19682, 26.59245,50.00000,20.00000,3.33168
542.80701,56.34000,      2.21400, 26.56192,50.00000,20.00000,3.33189
544.10602,56.47000,      2.23056, 26.51218,50.00000,20.00000,3.33215
545.40399,56.60000,      2.24747, 26.46243,50.00000,20.00000,3.33248
546.70001,56.73000,      2.26399, 26.40370,50.00000,20.00000,3.33287
547.99902,56.86000,      2.28046, 26.34385,50.00000,20.00000,3.33331
549.29999,56.99000,      2.29650, 26.32009,50.00000,20.00000,3.33382
550.59601,57.12000,      2.31203, 26.26691,50.00000,20.00000,3.33438
551.89697,57.25000,      2.32795, 26.21040,50.00000,20.00000,3.33500
553.19800,57.38000,      2.34438, 26.17309,50.00000,20.00000,3.33567
554.49597,57.51000,      2.35977, 26.11102,50.00000,20.00000,3.33640
555.79797,57.64000,      2.37156, 26.07705,50.00000,20.00000,3.33719
557.09698,57.77000,      2.38568, 26.02731,50.00000,20.00000,3.33803
558.39801,57.90000,      2.40147, 25.98333,50.00000,20.00000,3.33892
559.70099,58.03000,      2.41783, 25.91317,50.00000,20.00000,3.33987
561.00000,58.16000,      2.43323, 25.88607,50.00000,20.00000,3.34086
562.30200,58.29000,      2.44767, 25.83633,50.00000,20.00000,3.34191
563.60101,58.42000,      2.46247, 25.77982,50.00000,20.00000,3.34301
564.90100,58.55000,      2.47848, 25.73008,50.00000,20.00000,3.34415
566.19800,58.68000,      2.49279, 25.68823,50.00000,20.00000,3.34535
567.49597,58.81000,      2.50749, 25.62949,50.00000,20.00000,3.34659
568.79303,58.94000,      2.52171, 25.60007,50.00000,20.00000,3.34788
570.09100,59.07000,      2.53637, 25.54133,50.00000,20.00000,3.34921
571.39001,59.20000,      2.55118, 25.50180,50.00000,20.00000,3.35059
572.69202,59.33000,      2.56528, 25.46904,50.00000,20.00000,3.35202
573.99200,59.46000,      2.57982, 25.39555,50.00000,20.00000,3.35350
575.29102,59.59000,      2.59438, 25.36613,50.00000,20.00000,3.35501
576.59198,59.72000,      2.60804, 25.32437,50.00000,20.00000,3.35657
577.89502,59.85000,      2.62940, 25.26220,50.00000,20.00000,3.35817
579.19501,59.98000,      2.64717, 25.21923,50.00000,20.00000,3.35981
580.49597,60.11000,      2.66287, 25.16161,50.00000,20.00000,3.36150
581.79602,60.24000,      2.67760, 25.11409,50.00000,20.00000,3.36322
583.09601,60.37000,      2.68684, 25.06890,50.00000,20.00000,3.36498
584.39398,60.50000,      2.69909, 25.00784,50.00000,20.00000,3.36677
585.69598,60.63000,      2.71176, 24.96497,50.00000,20.00000,3.36861
586.99402,60.76000,      2.72495, 24.92655,50.00000,20.00000,3.37048
588.29498,60.89000,      2.73787, 24.86994,50.00000,20.00000,3.37238
589.59698,61.02000,      2.75039, 24.82586,50.00000,20.00000,3.37433
590.89600,61.15000,      2.76300, 24.78522,50.00000,20.00000,3.37630
592.19800,61.28000,      2.77492, 24.73214,50.00000,20.00000,3.37831
593.49902,61.41000,      2.78638, 24.67896,50.00000,20.00000,3.38035
594.79797,61.54000,      2.79807, 24.63600,50.00000,20.00000,3.38242
596.09802,61.67000,      2.80907, 24.59990,50.00000,20.00000,3.38452
597.40100,61.80000,      2.81989, 24.52752,50.00000,20.00000,3.38665
598.70398,61.93000,      2.83120, 24.49254,50.00000,20.00000,3.38882
600.00500,62.06000,      2.84118, 24.43825,50.00000,20.00000,3.39101
601.30902,62.19000,      2.85116, 24.39639,50.00000,20.00000,3.39323
602.60999,62.32000,      2.86118, 24.35120,50.00000,20.00000,3.39547
603.91498,62.45000,      2.87130, 24.29246,50.00000,20.00000,3.39775
605.21802,62.58000,      2.88061, 24.23706,50.00000,20.00000,3.40004
606.52002,62.71000,      2.88860, 24.19531,50.00000,20.00000,3.40236
607.82599,62.84000,      2.89687, 24.15113,50.00000,20.00000,3.40471
609.12598,62.97000,      2.91032, 24.10594,50.00000,20.00000,3.40707
610.42902,63.10000,      2.92315, 24.06419,50.00000,20.00000,3.40946
611.72498,63.23000,      2.93403, 24.01788,50.00000,20.00000,3.41185
613.02399,63.36000,      2.94439, 23.95793,50.00000,20.00000,3.41428
614.32098,63.49000,      2.95318, 23.93427,50.00000,20.00000,3.41671
615.61700,63.62000,      2.96094, 23.87099,50.00000,20.00000,3.41916
616.91699,63.75000,      2.97022, 23.82802,50.00000,20.00000,3.42164
618.21997,63.88000,      2.97759, 23.78283,50.00000,20.00000,3.42414
619.52100,64.01000,      2.98436, 23.73865,50.00000,20.00000,3.42665
620.82800,64.14000,      2.99174, 23.69467,50.00000,20.00000,3.42919
622.13397,64.27000,      2.99500, 23.63128,50.00000,20.00000,3.43173
623.43903,64.40000,      2.99984, 23.59064,50.00000,20.00000,3.43430
624.74402,64.53000,      3.00448, 23.55445,50.00000,20.00000,3.43687
626.04999,64.66000,      3.00967, 23.51037,50.00000,20.00000,3.43945
627.35303,64.79000,      3.01500, 23.44597,50.00000,20.00000,3.44205
628.65100,64.92000,      3.01981, 23.41321,50.00000,20.00000,3.44464
629.95203,65.05000,      3.02478, 23.37025,50.00000,20.00000,3.44724
631.25098,65.18000,      3.03065, 23.31940,50.00000,20.00000,3.44985
632.54901,65.31000,      3.03615, 23.26399,50.00000,20.00000,3.45247
633.84698,65.44000,      3.04193, 23.22103,50.00000,20.00000,3.45509
635.14697,65.57000,      3.04505, 23.17917,50.00000,20.00000,3.45772
636.44501,65.70000,      3.04871, 23.13853,50.00000,20.00000,3.46035
637.74597,65.83000,      3.05307, 23.08657,50.00000,20.00000,3.46300
639.04199,65.96000,      3.05738, 23.04592,50.00000,20.00000,3.46563
640.34302,66.09000,      3.06171, 22.98486,50.00000,20.00000,3.46828
641.63898,66.22000,      3.06507, 22.94978,50.00000,20.00000,3.47092
642.93597,66.35000,      3.06776, 22.90803,50.00000,20.00000,3.47357
644.23700,66.48000,      3.06970, 22.86395,50.00000,20.00000,3.47622
645.53900,66.61000,      3.07423, 22.82321,50.00000,20.00000,3.47887
646.83899,66.74000,      3.08083, 22.77468,50.00000,20.00000,3.48152
648.13702,66.87000,      3.08551, 22.71584,50.00000,20.00000,3.48416
649.43701,67.00000,      3.08888, 22.68875,50.00000,20.00000,3.48680
650.73297,67.13000,      3.09146, 22.64800,50.00000,20.00000,3.48943
652.03497,67.26000,      3.09471, 22.60392,50.00000,20.00000,3.49207
653.33801,67.39000,      3.09756, 22.54862,50.00000,20.00000,3.49470
654.63800,67.52000,      3.09981, 22.51577,50.00000,20.00000,3.49732
655.93903,67.65000,      3.10355, 22.47058,50.00000,20.00000,3.49994
657.23999,67.78000,      3.10685, 22.42761,50.00000,20.00000,3.50255
658.53699,67.91000,      3.11025, 22.38586,50.00000,20.00000,3.50514
659.83197,68.04000,      3.11324, 22.35300,50.00000,20.00000,3.50772
661.12598,68.17000,      3.11617, 22.30225,50.00000,20.00000,3.51029
662.41998,68.30000,      3.11790, 22.27283,50.00000,20.00000,3.51285
663.71503,68.43000,      3.12190, 22.22086,50.00000,20.00000,3.51539
665.00800,68.56000,      3.12629, 22.17678,50.00000,20.00000,3.51793
666.30402,68.69000,      3.12892, 22.11572,50.00000,20.00000,3.52045
667.59900,68.82000,      3.13052, 22.08185,50.00000,20.00000,3.52296
668.89801,68.95000,      3.13298, 22.04111,50.00000,20.00000,3.52546
670.19702,69.08000,      3.13479, 22.00502,50.00000,20.00000,3.52795
671.49597,69.21000,      3.13701, 21.96205,50.00000,20.00000,3.53042
672.79199,69.34000,      3.14045, 21.92252,50.00000,20.00000,3.53287
674.09100,69.47000,      3.14188, 21.88178,50.00000,20.00000,3.53531
675.38702,69.60000,      3.14231, 21.83093,50.00000,20.00000,3.53772
676.68903,69.73000,      3.14227, 21.78119,50.00000,20.00000,3.54012
677.99298,69.86000,      3.14172, 21.75409,50.00000,20.00000,3.54251
679.29498,69.99000,      3.14164, 21.71446,50.00000,20.00000,3.54488
680.59497,70.12000,      3.14272, 21.66139,50.00000,20.00000,3.54722
681.90100,70.25000,      3.14216, 21.61609,50.00000,20.00000,3.54955
683.20502,70.38000,      3.14179, 21.60265,50.00000,20.00000,3.55186
684.50598,70.51000,      3.14195, 21.54391,50.00000,20.00000,3.55413
685.81500,70.64000,      3.14307, 21.51105,50.00000,20.00000,3.55640
687.12201,70.77000,      3.14307, 21.45798,50.00000,20.00000,3.55864
688.42999,70.90000,      3.14464, 21.43078,50.00000,20.00000,3.56085
689.73297,71.03000,      3.14505, 21.40935,50.00000,20.00000,3.56303
691.03900,71.16000,      3.14629, 21.36183,50.00000,20.00000,3.56519
692.34198,71.29000,      3.14807, 21.31219,50.00000,20.00000,3.56732
693.64301,71.42000,      3.14881, 21.29298,50.00000,20.00000,3.56941
694.94598,71.55000,      3.15530, 21.23647,50.00000,20.00000,3.57149
696.24500,71.68000,      3.15987, 21.20938,50.00000,20.00000,3.57352
697.54401,71.81000,      3.16375, 21.16641,50.00000,20.00000,3.57553
698.84198,71.94000,      3.16854, 21.13810,50.00000,20.00000,3.57750
700.13300,72.07000,      3.17284, 21.10191,50.00000,20.00000,3.57943
701.42102,72.20000,      3.17738, 21.05783,50.00000,20.00000,3.58133
702.69800,72.33000,      3.18357, 21.01153,50.00000,20.00000,3.58318
703.95801,72.46000,      3.19117, 20.97766,50.00000,20.00000,3.58498
705.20203,72.59000,      3.20003, 20.94935,50.00000,20.00000,3.58672
706.41699,72.72000,      3.21090, 20.90194,50.00000,20.00000,3.58839
707.60999,72.85000,      3.22286, 20.87818,50.00000,20.00000,3.59000
708.77802,72.98000,      3.23524, 20.82389,50.00000,20.00000,3.59155
709.92200,73.11000,      3.24708, 20.79568,50.00000,20.00000,3.59304
711.04199,73.24000,      3.25846, 20.78203,50.00000,20.00000,3.59447
712.14099,73.37000,      3.26946, 20.73796,50.00000,20.00000,3.59585
713.21503,73.50000,      3.28029, 20.69731,50.00000,20.00000,3.59717
714.27399,73.63000,      3.29064, 20.67012,50.00000,20.00000,3.59845
715.30902,73.76000,      3.30053, 20.64080,50.00000,20.00000,3.59968
716.32501,73.89000,      3.31416, 20.59895,50.00000,20.00000,3.60086
717.32703,74.02000,      3.32534, 20.55709,50.00000,20.00000,3.60200
718.31000,74.15000,      3.33653, 20.51645,50.00000,20.00000,3.60309
719.27802,74.28000,      3.34617, 20.48713,50.00000,20.00000,3.60415
720.22601,74.41000,      3.35650, 20.45215,50.00000,20.00000,3.60516
721.16498,74.54000,      3.36667, 20.41141,50.00000,20.00000,3.60615
722.08502,74.67000,      3.37676, 20.36733,50.00000,20.00000,3.60709
722.98798,74.80000,      3.38658, 20.34701,50.00000,20.00000,3.60799
723.87903,74.93000,      3.39512, 20.32325,50.00000,20.00000,3.60887
724.75702,75.06000,      3.40273, 20.28595,50.00000,20.00000,3.60971
725.61902,75.19000,      3.41006, 20.24298,50.00000,20.00000,3.61052
726.46802,75.32000,      3.41872, 20.20123,50.00000,20.00000,3.61129
727.30103,75.45000,      3.42680, 20.17737,50.00000,20.00000,3.61204
728.12000,75.58000,      3.43585, 20.13895,50.00000,20.00000,3.61276
728.92200,75.71000,      3.44425, 20.10508,50.00000,20.00000,3.61344
729.71002,75.84000,      3.45257, 20.08587,50.00000,20.00000,3.61409
730.48999,75.97000,      3.45990, 20.04179,50.00000,20.00000,3.61473
731.25800,76.10000,      3.46997, 20.00004,50.00000,20.00000,3.61534
732.01898,76.23000,      3.47843, 19.97285,50.00000,20.00000,3.61592
732.76501,76.36000,      3.48527, 19.94565,50.00000,20.00000,3.61648
733.50299,76.49000,      3.49242, 19.90046,50.00000,20.00000,3.61703
734.23102,76.62000,      3.50034, 19.85982,50.00000,20.00000,3.61754
734.94598,76.75000,      3.50654, 19.84627,50.00000,20.00000,3.61804
735.65601,76.88000,      3.51336, 19.81907,50.00000,20.00000,3.61852
736.35498,77.01000,      3.52138, 19.78521,50.00000,20.00000,3.61897
737.04102,77.14000,      3.52805, 19.75811,50.00000,20.00000,3.61941
737.71698,77.27000,      3.53468, 19.72991,50.00000,20.00000,3.61983
738.38501,77.40000,      3.54140, 19.69937,50.00000,20.00000,3.62023
739.04303,77.53000,      3.54808, 19.66096,50.00000,20.00000,3.62061
739.69098,77.66000,      3.55441, 19.62709,50.00000,20.00000,3.62097
740.32703,77.79000,      3.56115, 19.60667,50.00000,20.00000,3.62132
740.95599,77.92000,      3.56683, 19.56936,50.00000,20.00000,3.62165
741.57397,78.05000,      3.57316, 19.54227,50.00000,20.00000,3.62196
742.18402,78.18000,      3.57898, 19.51517,50.00000,20.00000,3.62226
742.78699,78.31000,      3.58508, 19.48454,50.00000,20.00000,3.62255
743.37799,78.44000,      3.59182, 19.45745,50.00000,20.00000,3.62282
743.96399,78.57000,      3.59774, 19.41681,50.00000,20.00000,3.62308
744.53802,78.70000,      3.60307, 19.38961,50.00000,20.00000,3.62332
745.10303,78.83000,      3.60859, 19.36252,50.00000,20.00000,3.62355
745.66199,78.96000,      3.61353, 19.33886,50.00000,20.00000,3.62377
746.20801,79.09000,      3.61745, 19.31166,50.00000,20.00000,3.62397
746.75201,79.22000,      3.62139, 19.27780,50.00000,20.00000,3.62417
747.28601,79.35000,      3.62497, 19.25404,50.00000,20.00000,3.62435
747.81000,79.48000,      3.62982, 19.21340,50.00000,20.00000,3.62452
748.33002,79.61000,      3.63496, 19.19297,50.00000,20.00000,3.62468
748.83899,79.74000,      3.63932, 19.15233,50.00000,20.00000,3.62484
749.34100,79.87000,      3.65035, 19.12524,50.00000,20.00000,3.62498
749.83801,80.00000,      3.65702, 19.09127,50.00000,20.00000,3.62511
750.32703,80.13000,      3.66285, 19.08450,50.00000,20.00000,3.62523
750.80499,80.26000,      3.66838, 19.04274,50.00000,20.00000,3.62535
751.27899,80.39000,      3.67348, 19.01555,50.00000,20.00000,3.62545
751.74597,80.52000,      3.67813, 18.96480,50.00000,20.00000,3.62555
752.20300,80.65000,      3.68240, 18.93770,50.00000,20.00000,3.62564
752.65698,80.78000,      3.68631, 18.92405,50.00000,20.00000,3.62572
753.10498,80.91000,      3.69060, 18.89019,50.00000,20.00000,3.62580
753.54602,81.04000,      3.69457, 18.86188,50.00000,20.00000,3.62586
753.98602,81.17000,      3.69885, 18.83478,50.00000,20.00000,3.62593
754.41101,81.30000,      3.70196, 18.80769,50.00000,20.00000,3.62598
754.83502,81.43000,      3.70570, 18.76695,50.00000,20.00000,3.62603
755.25000,81.56000,      3.70938, 18.73641,50.00000,20.00000,3.62607
755.65997,81.69000,      3.71570, 18.72287,50.00000,20.00000,3.62611
756.06897,81.82000,      3.72028, 18.68213,50.00000,20.00000,3.62614
756.46503,81.95000,      3.72509, 18.65503,50.00000,20.00000,3.62616
756.85498,82.08000,      3.72934, 18.63137,50.00000,20.00000,3.62618
757.24597,82.21000,      3.73375, 18.59407,50.00000,20.00000,3.62620
757.62598,82.34000,      3.73772, 18.58386,50.00000,20.00000,3.62621
758.00403,82.47000,      3.74194, 18.55333,50.00000,20.00000,3.62622
758.37598,82.60000,      3.74594, 18.52967,50.00000,20.00000,3.62622
758.74200,82.73000,      3.74992, 18.49459,50.00000,20.00000,3.62622
759.10498,82.86000,      3.75435, 18.47083,50.00000,20.00000,3.62621
759.46002,82.99000,      3.75811, 18.45385,50.00000,20.00000,3.62620
759.81500,83.12000,      3.76163, 18.41320,50.00000,20.00000,3.62618
760.16400,83.25000,      3.76525, 18.39622,50.00000,20.00000,3.62617
760.50598,83.38000,      3.76882, 18.36225,50.00000,20.00000,3.62614
760.84802,83.51000,      3.77238, 18.33859,50.00000,20.00000,3.62612
761.18201,83.64000,      3.77600, 18.31827,50.00000,20.00000,3.62609
761.51703,83.77000,      3.77916, 18.27975,50.00000,20.00000,3.62606
761.84198,83.90000,      3.78286, 18.25266,50.00000,20.00000,3.62603
762.16199,84.03000,      3.78647, 18.22567,50.00000,20.00000,3.62599
762.47601,84.16000,      3.78972, 18.20868,50.00000,20.00000,3.62595
762.78802,84.29000,      3.79321, 18.18149,50.00000,20.00000,3.62591
763.09497,84.42000,      3.79621, 18.14085,50.00000,20.00000,3.62586
763.40100,84.55000,      3.79871, 18.11254,50.00000,20.00000,3.62581
763.69702,84.68000,      3.80074, 18.08544,50.00000,20.00000,3.62577
763.99103,84.81000,      3.80377, 18.04137,50.00000,20.00000,3.62571
764.28101,84.94000,      3.80713, 18.03004,50.00000,20.00000,3.62566
764.57001,85.07000,      3.81027, 18.00295,50.00000,20.00000,3.62561
764.85303,85.20000,      3.81343, 17.97242,50.00000,20.00000,3.62555
765.13300,85.33000,      3.81665, 17.94532,50.00000,20.00000,3.62549
765.40698,85.46000,      3.82030, 17.91479,50.00000,20.00000,3.62543
765.68103,85.59000,      3.82382, 17.89437,50.00000,20.00000,3.62537
765.94800,85.72000,      3.82467, 17.86727,50.00000,20.00000,3.62530
766.21301,85.85000,      3.82676, 17.84018,50.00000,20.00000,3.62524
766.47400,85.98000,      3.82951, 17.80965,50.00000,20.00000,3.62517
766.73297,86.11000,      3.83175, 17.78255,50.00000,20.00000,3.62510
766.98999,86.24000,      3.83436, 17.77234,50.00000,20.00000,3.62503
767.23901,86.37000,      3.83680, 17.74525,50.00000,20.00000,3.62496
767.48999,86.50000,      3.83945, 17.71128,50.00000,20.00000,3.62489
767.73798,86.63000,      3.84199, 17.68419,50.00000,20.00000,3.62482
767.97998,86.76000,      3.84501, 17.67064,50.00000,20.00000,3.62475
768.22198,86.89000,      3.84766, 17.62990,50.00000,20.00000,3.62467
768.46002,87.02000,      3.85021, 17.61635,50.00000,20.00000,3.62459
768.69397,87.15000,      3.85261, 17.58248,50.00000,20.00000,3.62452
768.92902,87.28000,      3.85518, 17.55529,50.00000,20.00000,3.62444
769.15900,87.41000,      3.85804, 17.52819,50.00000,20.00000,3.62436
769.38599,87.54000,      3.86052, 17.50110,50.00000,20.00000,3.62428
769.60699,87.67000,      3.86280, 17.48421,50.00000,20.00000,3.62420
769.82300,87.80000,      3.86612, 17.45591,50.00000,20.00000,3.62412
770.03497,87.93000,      3.86946, 17.42881,50.00000,20.00000,3.62405
770.23901,88.06000,      3.87214, 17.40172,50.00000,20.00000,3.62397
770.44299,88.19000,      3.87505, 17.36775,50.00000,20.00000,3.62389
770.64099,88.32000,      3.87743, 17.33044,50.00000,20.00000,3.62381
770.83502,88.45000,      3.87975, 17.29991,50.00000,20.00000,3.62374
771.03101,88.58000,      3.88194, 17.28525,50.00000,20.00000,3.62366
771.22400,88.71000,      3.88437, 17.25816,50.00000,20.00000,3.62358
771.41400,88.84000,      3.88701, 17.23096,50.00000,20.00000,3.62350
771.60199,88.97000,      3.88880, 17.20387,50.00000,20.00000,3.62342
771.78998,89.10000,      3.89089, 17.16656,50.00000,20.00000,3.62334
771.97498,89.23000,      3.89329, 17.16666,50.00000,20.00000,3.62326
772.15900,89.36000,      3.89559, 17.15302,50.00000,20.00000,3.62318
772.33600,89.49000,      3.89849, 17.10216,50.00000,20.00000,3.62310
772.51398,89.62000,      3.90158, 17.07507,50.00000,20.00000,3.62302
772.69397,89.75000,      3.90426, 17.04787,50.00000,20.00000,3.62293
772.86798,89.88000,      3.90665, 17.03099,50.00000,20.00000,3.62285
773.04401,90.01000,      3.90925, 16.99702,50.00000,20.00000,3.62277
773.20898,90.14000,      3.91149, 16.96649,50.00000,20.00000,3.62269
773.38000,90.27000,      3.91371, 16.93940,50.00000,20.00000,3.62261
773.54401,90.40000,      3.91594, 16.91230,50.00000,20.00000,3.62253
773.70898,90.53000,      3.91833, 16.88511,50.00000,20.00000,3.62245
773.86499,90.66000,      3.92097, 16.87156,50.00000,20.00000,3.62237
774.02100,90.79000,      3.92352, 16.85124,50.00000,20.00000,3.62229
774.17902,90.92000,      3.92580, 16.83092,50.00000,20.00000,3.62221
774.33197,91.05000,      3.92808, 16.79017,50.00000,20.00000,3.62213
774.48499,91.18000,      3.93041, 16.77552,50.00000,20.00000,3.62205
774.63397,91.31000,      3.93309, 16.74842,50.00000,20.00000,3.62197
774.78003,91.44000,      3.93517, 16.72123,50.00000,20.00000,3.62190
774.92499,91.57000,      3.93737, 16.69757,50.00000,20.00000,3.62182
775.07202,91.70000,      3.93933, 16.66593,50.00000,20.00000,3.62174
775.21198,91.83000,      3.94094, 16.64894,50.00000,20.00000,3.62166
775.35101,91.96000,      3.94316, 16.61507,50.00000,20.00000,3.62159
775.37299,91.98000,      3.94342, 16.61507,50.00000,20.00000,3.62158